Workbook
Name curr: [2]Lists!$B$7:$B$32
Name curr: [2]Lists!$B$7:$B$32
Name curr: [2]Lists!$B$7:$B$32
Name curr: [1]Lists!$B$7:$B$32
Name curr_table: [2]Lists!$B$7:$F$32
Name curr_table: [2]Lists!$B$7:$F$32
Name curr_table: [2]Lists!$B$7:$F$32
Name curr_table: [1]Lists!$B$7:$F$32
Name status: [2]Lists!$H$7:$H$9
Name status: [2]Lists!$H$7:$H$9
Name status: [2]Lists!$H$7:$H$9
Name status: [1]Lists!$H$7:$H$9
Name TV_growth: '[1]A. Cover'!$D$13
Name TV_growth: '[2]A. Cover'!$D$13
Name TV_growth: '[2]A. Cover'!$D$13
Name TV_growth: '[2]A. Cover'!$D$13
Name tv_growth: Inputs!$C$19
Name wacc: '[1]A. Cover'!$D$12
Name wacc: '[2]A. Cover'!$D$12
Name wacc: '[2]A. Cover'!$D$12
Name wacc: '[2]A. Cover'!$D$12
Name wacc: Inputs!$C$18
Name years: [2]Lists!$J$7:$J$12
Name years: [2]Lists!$J$7:$J$12
Name years: [2]Lists!$J$7:$J$12
Name years: [1]Lists!$J$7:$J$12
Name Yr0: '[2]A. Cover'!$D$9
Name Yr0: '[2]A. Cover'!$D$9
Name Yr0: '[2]A. Cover'!$D$9
Name Yr0: '[1]A. Cover'!$D$9

Sheet Overview
B2: Welcome to the Project Financial Model
B4: Overall Purpose
B5: This model is designed to be used to help financially evaluate a range of programs and projects. Specifically it should help to;
B6: R | C6: Identify the wide range of variables that should be considered when evaluating a project
B7: R | C7: Help identify possible costs and savings that may otherwise be missed
B8: R | C8: Provide guidance on how those costs and savings should be identified and measured
B9: R | C9: Be a simple spreadsheet to calculate the savings and the financial metrics
B10: R | C10: Provide a consistent Mgt summary with the key financial data so that go/no-go decisions can be made quickly
B11: R | C11: Help evaluate & compare projects in a similar manner such that capital allocation priority callscan be made
B13: Methodology
B14: This model provides an incremental assessment on the impact of a course of action. It requires the user to understand all applicable scenarios how they impact following the changing of the variables. The model can then assess the financial impact of the project, and describe that in the following ways;
B15:  | C15: Cash Flow
B16:  | C16: Net Present Value (NPV)
B17:  | C17: Sales (growth)
B18:  | C18: Costs (investments, cost saves, expenses, capital expense)
B19:  | C19: Profit
B20:  | C20: Payback (time)
B21:  | C21: Return on Capital Invested (ROIC)
B22: Of these the primary method for evalution is Cash Flow and NPV.
B24: How To Use the model
B25: Try to to complete the moedl in the following order;
C26: 1. Inputs Tab | D26: Project Information and descriptions. Take your time here as the inputs feed the modeling sheets.
C27: 2. Checklist | D27: Use the Checklist to help identify all the variables that might be impacted by your project and begin to pull together the details to complete the workbook. Use the filter on left hand side to selct the type of porject you are evaluating, and this will list the variables most likely to be impacted. Use the Glossary to help undestand how to measure your varaibles.
C28: 3. Model (1-7): Current State | D28: Establish your Scenarios, and complete in each tab of the model. You only need to focus on the subset of varibales that are relevant to the project.
C29: 4. Model (1-7): Future State | D29: Establish your Scenarios, and complete in each tab of the model. You only need to focus on the subset of varibales that are relevant to the project, and thereby ensure that the comparison to the Current State is a fair one.
C30: 5. Scenarios | D30: Summary of all scenarios
C31: 6. Compare | D31: Select which scenarios you want to compare and asses the variance, NPV, payback period, etc.
B33: The Model
B34: Please ensure you are using the latest veriosn of the model & reach out to the owner of the model of any questions, suggested modifications, found errors etc.
B36: The current owner of this model is:
B39: Current Version of the model is:
C40: v1.4

Sheet FAQs
E2: FAQ
E5: Why do we focus on cash generation to evaluate a project and not just profit?
B6: =IFERROR(RANK($C6,$C$6:$C$408,1),"") -> 1 | C6: =IFERROR(SEARCH([2]FAQ!$D$4,$E6)+ROW()/1000,"") -> 1.006 | E6: Cash generation is often considered the best measure for evaluating a business project because it directly reflects the amount of cash a project generates over a specific period. This is important because cash is what ultimately funds a business's operations and investments, and it's also what allows a company to pay off its debts, distribute dividends to shareholders, and reinvest in the business. In contrast, other financial measures like profits or revenues can be manipulated by accounting practices or timing differences, and may not accurately reflect the actual cash flow of a business. For example, a company may report high profits but still have trouble paying its bills if those profits are tied up in inventory.
E7: What is NPV and why do we use that?
B8: =IFERROR(RANK($C8,$C$6:$C$408,1),"") -> 2 | C8: =IFERROR(SEARCH([2]FAQ!$D$4,$E8)+ROW()/1000,"") -> 1.008 | E8: Net Present Value (NPV) is one of the most widely used measures for evaluating whether to proceed with a project or not. NPV is calculated by subtracting the present value of a project's cash outflows from the present value of its cash inflows. If the resulting NPV is positive, the project is expected to generate a return greater than the cost of capital, and therefore may be worth pursuing. The advantages of using NPV as a measure for project evaluation are: - It accounts for the time value of money: NPV adjusts future cash flows to their present values, taking into consideration the opportunity cost of investing money today versus in the future. - It considers all cash flows: NPV includes both the initial investment and all future cash flows associated with the project, providing a more comprehensive view of the project's profitability. - It provides a clear measure of profitability: NPV is expressed in monetary terms, making it easy to compare different projects and determine which one generates the highest return. However, there are also some limitations to using NPV as the sole measure for project evaluation. For example, it assumes that cash flows are known with certainty, which may not always be the case. NPV also doesn't consider non-financial factors such as environmental or social impacts, which may be important for some projects. Therefore, while NPV is a useful tool for evaluating projects, it should be used in conjunction with other measures and with consideration of other important factors to make informed decisions.
B9: =IFERROR(RANK($C9,$C$6:$C$408,1),"") -> 3 | C9: =IFERROR(SEARCH([2]FAQ!$D$4,$E9)+ROW()/1000,"") -> 1.009 | E9: How do I evaluate the cost save of reducing sidetracks?
E10: Eliminating sidetracks primarily enables increased productivity (less waiting) and also lower inventory (increases cashflow) and is definitely worth measuring within the project! In order to financially measure the increased productivity you should try and estimate the number of hours that are saved by eliminating the sidetracks. Measure the cycle time at current state, and then compare to the cycle time with the sidetracks (or other productivity impacts) eliminated --> the difference should be measured as a unit of time. Next step would be to then turn the saved time into a financial metric (usually done by using the average labour cost expressed per day/hour). And don't forget to include the Inventory reductions included in the model -- these are valuable since they mean we have less cash tied up in inventory.
B11: =IFERROR(RANK($C11,$C$6:$C$408,1),"") -> 4 | C11: =IFERROR(SEARCH([2]FAQ!$D$4,$E11)+ROW()/1000,"") -> 1.011 | E11: Should I count to cost of changing production schedules?
E12: Any change to product schedules, or cycles times, should be included if it has an impact on production efficiency. Try to assess the impact (positive or negative) in terms of labour hours, and then this can be translated into a financial metric in terms of cost. Speak to your finance business parnter to agree the right cost metric to use.
B13: =IFERROR(RANK($C13,$C$6:$C$408,1),"") -> 5 | C13: =IFERROR(SEARCH([2]FAQ!$D$4,$E13)+ROW()/1000,"") -> 1.013 | E13: How should I evaluate tax?
E14: Tax is something that impacts cashflow and should be included therefore in any NPV and ROIC calculations. Tax is usually applied to any incremental profits made in a project, using the country's local Corp tax rate which can be found out by asking the Corp Tax team. If the project involves moving profits from one country to another then there may be a difference in Corp tax rates in those countries and the difference should be counted in the project using the tax worksheet. If moving country profits you should also ask the tax team to identify if there are any unused tax credits that can be utilised and these should be dedcuted from the taxable gain. If in doubt ask your finance partner.
B15: =IFERROR(RANK($C15,$C$6:$C$408,1),"") -> 6 | C15: =IFERROR(SEARCH([2]FAQ!$D$4,$E15)+ROW()/1000,"") -> 1.015 | E15: Should the current state equal the latest financial forecast?
E16: The current state should be the "do nothing" scenario and ideally that would equal the latest financial forecast. If not then talk to your local finance rep to find out why not and if the financial foreacst should be updated. Nevertheless when assessing current adn future states you only need to appraise the elements of the financials that are relvant to the project you are appraising. For example, if you are looking at a project related to Encore Pumper volumes, then you should only include the volumes associated to Encore Pumpers in the before and after states, and not all Encore units.
B17: =IFERROR(RANK($C17,$C$6:$C$408,1),"") -> 7 | C17: =IFERROR(SEARCH([2]FAQ!$D$4,$E17)+ROW()/1000,"") -> 1.017 | E17: Do I need a financial analyst to help fill this in?
E18: No - this model can be used by any project team member. However it is quite comprehensive and so feel free to reach out to your finance business partner for support and guidance. For all large projects, dedicated finance support should be identified and made available in order to help assess the inputs and manage the financial impacts.
B19: =IFERROR(RANK($C19,$C$6:$C$408,1),"") -> 8 | C19: =IFERROR(SEARCH([2]FAQ!$D$4,$E19)+ROW()/1000,"") -> 1.019 | E19: How should I calculate the average COGS?
E20: By speaking to operations or your finance business partner you should isolate the total COGS associated with the product or part that you are assessing, and simply divide by the total number of units. It is usually helpful to think of averages instead of working our every permitation, but be careful to assess like for like. If in doubt then work with your finance business poartner.
B21: =IFERROR(RANK($C21,$C$6:$C$408,1),"") -> 9 | C21: =IFERROR(SEARCH([2]FAQ!$D$4,$E21)+ROW()/1000,"") -> 1.021 | E21: How should I calculate potential future PPV savings?
B22: =IFERROR(RANK($C22,$C$6:$C$408,1),"") -> 10 | C22: =IFERROR(SEARCH([2]FAQ!$D$4,$E22)+ROW()/1000,"") -> 1.022 | E22: First you should brainstorm all the ways that the project might change the supply chain. The main areas where PPV might be able to be achieved is if you are increasing volumes to a particular supplier, either through part consolidation, or increased throughput or other means. You should then work with the supply chain team to identify a tarageted price reduction based on those chnages that we thinkwe can ask the supplier for.
B23: =IFERROR(RANK($C23,$C$6:$C$408,1),"") | C23: =IFERROR(SEARCH([2]FAQ!$D$4,$E23)+ROW()/1000,"")
B24: =IFERROR(RANK($C24,$C$6:$C$408,1),"") | C24: =IFERROR(SEARCH([2]FAQ!$D$4,$E24)+ROW()/1000,"")
B25: =IFERROR(RANK($C25,$C$6:$C$408,1),"") | C25: =IFERROR(SEARCH([2]FAQ!$D$4,$E25)+ROW()/1000,"")
B26: =IFERROR(RANK($C26,$C$6:$C$408,1),"") | C26: =IFERROR(SEARCH([2]FAQ!$D$4,$E26)+ROW()/1000,"")
B27: =IFERROR(RANK($C27,$C$6:$C$408,1),"") | C27: =IFERROR(SEARCH([2]FAQ!$D$4,$E27)+ROW()/1000,"")
B28: =IFERROR(RANK($C28,$C$6:$C$408,1),"") | C28: =IFERROR(SEARCH([2]FAQ!$D$4,$E28)+ROW()/1000,"")
B29: =IFERROR(RANK($C29,$C$6:$C$408,1),"") | C29: =IFERROR(SEARCH([2]FAQ!$D$4,$E29)+ROW()/1000,"")
B30: =IFERROR(RANK($C30,$C$6:$C$408,1),"") | C30: =IFERROR(SEARCH([2]FAQ!$D$4,$E30)+ROW()/1000,"")
B31: =IFERROR(RANK($C31,$C$6:$C$408,1),"") | C31: =IFERROR(SEARCH([2]FAQ!$D$4,$E31)+ROW()/1000,"")
C32: =IFERROR(SEARCH([2]FAQ!$D$4,$E32)+ROW()/1000,"")
C33: =IFERROR(SEARCH([2]FAQ!$D$4,$E33)+ROW()/1000,"")
C34: =IFERROR(SEARCH([2]FAQ!$D$4,$E34)+ROW()/1000,"")
C35: =IFERROR(SEARCH([2]FAQ!$D$4,$E35)+ROW()/1000,"")
C36: =IFERROR(SEARCH([2]FAQ!$D$4,$E36)+ROW()/1000,"")
C37: =IFERROR(SEARCH([2]FAQ!$D$4,$E37)+ROW()/1000,"")
C38: =IFERROR(SEARCH([2]FAQ!$D$4,$E38)+ROW()/1000,"")
C39: =IFERROR(SEARCH([2]FAQ!$D$4,$E39)+ROW()/1000,"")
C40: =IFERROR(SEARCH([2]FAQ!$D$4,$E40)+ROW()/1000,"")
C41: =IFERROR(SEARCH([2]FAQ!$D$4,$E41)+ROW()/1000,"")
C42: =IFERROR(SEARCH([2]FAQ!$D$4,$E42)+ROW()/1000,"")
C43: =IFERROR(SEARCH([2]FAQ!$D$4,$E43)+ROW()/1000,"")
...

Sheet Inputs
B2: Inputs
B4: Project Name:
B5: Project Description:
B7: PY-2 | C7: =IF(C8="","",C8-1) -> 2023
B8: PY-1 | C8: =IF(C9="","",C9-1) -> 2024
B9: Prior Year (PY): | C9: =IF(C10="","",C10-1) -> 2025
B10: Current Year (CY): | C10: 2026
B11: CY+1: | C11: =IF(C10="","",C10+1) -> 2027
B12: CY+2: | C12: =IF(C11="","",C11+1) -> 2028
B13: CY+3: | C13: =IF(C12="","",C12+1) -> 2029
B14: CY+4: | C14: =IF(C13="","",C13+1) -> 2030
B16: Model Currency: | C16: USD
B18: Weighted Avg Cost of Capital (WACC): | C18: 0.1
B19: Terminal Value (TV) Growth Rate: | C19: 0.03
B21: Scenario Name | C21: Scenario Description
B22: Scenario 1 | C22: =B22&" Description" -> Scenario 1 Description
B23: Scenario 2 | C23: =B23&" Description" -> Scenario 2 Description
B24: Scenario 3 | C24: =B24&" Description" -> Scenario 3 Description
B25: Scenario 4 | C25: =B25&" Description" -> Scenario 4 Description
B26: Scenario 5 | C26: =B26&" Description" -> Scenario 5 Description

Sheet Checklist
J2: Glossary of Items: Simplification Projects
B8: 1 | C8: 2 | D8: 3 | E8: 4 | F8: 5 | G8: 6 | H8: 7 | L8: Item | M8: Status | N8: Assumptions | O8: Page
L9: Name of the variable that is changing | N9: Comments and notes -- further detail should be added on individual worksheets | O9: find back up
B11: l | D11: l | F11: l | G11: l | H11: l | J11: VARIABLE | K11: 1 | L11: Revenue | M11: Need
B12: l | D12: l | F12: l | G12: l | H12: l | K12: 2 | L12: Price | M12: Need
B13: l | C13: l | D13: l | E13: l | F13: l | G13: l | H13: l | J13: Directly attributable cost associated with the product itself Vaiances to standard cost driven by productivity | K13: 3 | L13: Material cost of part | M13: Need
B14: l | C14: l | D14: l | E14: l | F14: l | G14: l | H14: l | K14: 4 | L14: Direct Labour | M14: Need
B15: l | C15: l | D15: l | E15: l | F15: l | G15: l | H15: l | K15: 5 | L15: Inbound Freight | M15: Need
B16: l | C16: l | D16: l | E16: l | F16: l | G16: l | H16: l | K16: 6 | L16: Outbound Freight | M16: Need
B17: l | C17: l | D17: l | E17: l | F17: l | G17: l | H17: l | K17: 7 | L17: Duties and Import taxes | M17: Need
B18: l | C18: l | D18: l | E18: l | F18: l | G18: l | H18: l | K18: 8 | L18: Overtime / Labour Variance | M18: Need
B19: l | C19: l | D19: l | E19: l | F19: l | G19: l | H19: l | K19: 9 | L19: PPV | M19: Need
B20: l | C20: l | D20: l | E20: l | F20: l | G20: l | H20: l | K20: 10 | L20: E&O | M20: Need
B21: l | C21: l | D21: l | E21: l | F21: l | G21: l | H21: l | K21: 11 | L21: Scrap | M21: Need
B22: l | C22: l | D22: l | E22: l | F22: l | G22: l | H22: l | K22: 12 | L22: Warranty | M22: Need
B23: l | C23: l | D23: l | F23: l | G23: l | H23: l | J23: Fixed OHCOGS | K23: 14 | L23: Quality | M23: Need
B24: l | D24: l | F24: l | G24: l | H24: l | K24: 15 | L24: VBS | M24: Need
B25: l | D25: l | F25: l | G25: l | H25: l | K25: 16 | L25: Customer Service | M25: Need
B26: l | D26: l | F26: l | G26: l | H26: l | K26: 17 | L26: Operations Supervisors | M26: Need
B27: l | C27: l | D27: l | F27: l | G27: l | H27: l | K27: 18 | L27: Purchasing | M27: Need
B28: l | C28: l | D28: l | F28: l | G28: l | H28: l | K28: 19 | L28: Factory consumables (paint, PPE, oil, testing) | M28: Need
B29: l | C29: l | D29: l | F29: l | G29: l | H29: l | K29: 20 | L29: Contract services - maintenance, security, leasing, general consulting | M29: Need
B30: l | D30: l | F30: l | G30: l | H30: l | K30: 21 | L30: Property Taxes | M30: Need
B31: l | D31: l | F31: l | G31: l | H31: l | K31: 22 | L31: Insurance | M31: Need
B32: l | D32: l | F32: l | G32: l | H32: l | K32: 23 | L32: Environmental costs - including reserves | M32: Need
B33: l | D33: l | F33: l | G33: l | H33: l | K33: 24 | L33: Factory Maintenance | M33: Need
B34: l | D34: l | F34: l | G34: l | H34: l | K34: 25 | L34: Shared Services (canteen, cleaning …) | M34: Need
B35: l | D35: l | F35: l | G35: l | H35: l | K35: 26 | L35: Utilities (water, electricity, gas) | M35: Need
B36: l | D36: l | F36: l | J36: OPEX | K36: 27 | L36: HR | M36: Need
B37: l | D37: l | F37: l | K37: 28 | L37: Finance | M37: Need
B38: l | D38: l | F38: l | K38: 29 | L38: IT | M38: Need
B39: l | D39: l | E39: l | F39: l | H39: l | K39: 30 | L39: Sustaining Engineering | M39: Need
B40: l | D40: l | F40: l | K40: 31 | L40: Sales | M40: Need
B41: l | D41: l | F41: l | K41: 32 | L41: Marketing | M41: Need
B42: l | D42: l | E42: l | F42: l | K42: 33 | L42: 3rd party services - IT, Engineering, Marketing, general consulting, payroll | M42: Need
B43: l | D43: l | F43: l | G43: l | H43: l | J43: Investment | K43: 34 | L43: Restructuring expense | M43: Need
B44: l | C44: l | D44: l | E44: l | F44: l | G44: l | H44: l | K44: 35 | L44: 3rd party expenses | M44: Need
B45: l | C45: l | D45: l | E45: l | F45: l | G45: l | H45: l | K45: 36 | L45: Fixed asset write off | M45: Need
B46: l | C46: l | D46: l | E46: l | F46: l | G46: l | H46: l | K46: 37 | L46: E&O/Write off of inventory impact | M46: Need
B47: l | C47: l | D47: l | E47: l | F47: l | G47: l | H47: l | K47: 38 | L47: Capital Expenditures | M47: Need
...

Sheet Compare
B3: =IF(Inputs!C4="","[Insert Project Name in Inputs Tab]",Inputs!C4) -> [Insert Project Name in Inputs Tab] | D3: Variance | M3: Select>> | N3: Select Scenario | W3: Select>> | X3: Select Scenario
B4: (000s) | N4: =IFERROR(_xlfn.XLOOKUP(N3,Inputs!B22:B26,Inputs!C22:C26,""),"") | X4: =IFERROR(_xlfn.XLOOKUP(X3,Inputs!B22:B26,Inputs!C22:C26,""),"")
D6: 2023 | E6: 2024 | F6: 2025 | G6: 2026 | H6: 2027 | I6: 2028 | J6: 2029 | K6: 2030 | N6: {=IF($N$3="Select Scenario","", IF($N$3=Scenarios!D2,Scenarios!D5:K48, IF($N$3=Scenarios!M2,Scenarios!M5:T48, IF($N$3=Scenarios!V2,Scenarios!V5:AC48, IF($N$3=Scenarios!AE2,Scenarios!AE5:AL48, IF($N$3=Scenarios!AN2,Scenarios!AN5:AU48, IF($N$3=Scenarios!AW2,Scenarios!AW5:BD48,"")))))))} | X6: {=IF($X$3="Select Scenario","", IF($X$3=Scenarios!D2,Scenarios!D5:K48, IF($X$3=Scenarios!M2,Scenarios!M5:T48, IF($X$3=Scenarios!V2,Scenarios!V5:AC48, IF($X$3=Scenarios!AE2,Scenarios!AE5:AL48, IF($X$3=Scenarios!AN2,Scenarios!AN5:AU48, IF($X$3=Scenarios!AW2,Scenarios!AW5:BD48,"")))))))}
B7: Net Sales | C7: (000) | D7: =N7-X7 -> 0 | E7: =O7-Y7 -> 0 | F7: =P7-Z7 -> 0 | G7: =Q7-AA7 -> 0 | H7: =R7-AB7 -> 0 | I7: =S7-AC7 -> 0 | J7: =T7-AD7 -> 0 | K7: =U7-AE7 -> 0
B9: Direct Margin | C9: (000) | D9: =N9-X9 -> 0 | E9: =O9-Y9 -> 0 | F9: =P9-Z9 -> 0 | G9: =Q9-AA9 -> 0 | H9: =R9-AB9 -> 0 | I9: =S9-AC9 -> 0 | J9: =T9-AD9 -> 0 | K9: =U9-AE9 -> 0
B10: Direct Margin % | D10: =N10-X10 -> 0 | E10: =O10-Y10 -> 0 | F10: =P10-Z10 -> 0 | G10: =Q10-AA10 -> 0 | H10: =R10-AB10 -> 0 | I10: =S10-AC10 -> 0 | J10: =T10-AD10 -> 0 | K10: =U10-AE10 -> 0
B12: Variances | C12: (000) | D12: =N12-X12 -> 0 | E12: =O12-Y12 -> 0 | F12: =P12-Z12 -> 0 | G12: =Q12-AA12 -> 0 | H12: =R12-AB12 -> 0 | I12: =S12-AC12 -> 0 | J12: =T12-AD12 -> 0 | K12: =U12-AE12 -> 0
B13: OHCOGS | C13: (000) | D13: =N13-X13 -> 0 | E13: =O13-Y13 -> 0 | F13: =P13-Z13 -> 0 | G13: =Q13-AA13 -> 0 | H13: =R13-AB13 -> 0 | I13: =S13-AC13 -> 0 | J13: =T13-AD13 -> 0 | K13: =U13-AE13 -> 0
B15: Gross Profit | C15: (000) | D15: =D9-SUM(D12:D13) -> 0 | E15: =E9-SUM(E12:E13) -> 0 | F15: =F9-SUM(F12:F13) -> 0 | G15: =G9-SUM(G12:G13) -> 0 | H15: =H9-SUM(H12:H13) -> 0 | I15: =I9-SUM(I12:I13) -> 0 | J15: =J9-SUM(J12:J13) -> 0 | K15: =K9-SUM(K12:K13) -> 0
B16: Gross Profit % | D16: =N16-X16 -> 0 | E16: =O16-Y16 -> 0 | F16: =P16-Z16 -> 0 | G16: =Q16-AA16 -> 0 | H16: =R16-AB16 -> 0 | I16: =S16-AC16 -> 0 | J16: =T16-AD16 -> 0 | K16: =U16-AE16 -> 0
B18: R&D | C18: (000) | D18: =N18-X18 -> 0 | E18: =O18-Y18 -> 0 | F18: =P18-Z18 -> 0 | G18: =Q18-AA18 -> 0 | H18: =R18-AB18 -> 0 | I18: =S18-AC18 -> 0 | J18: =T18-AD18 -> 0 | K18: =U18-AE18 -> 0
B19: S&M | C19: (000) | D19: =N19-X19 -> 0 | E19: =O19-Y19 -> 0 | F19: =P19-Z19 -> 0 | G19: =Q19-AA19 -> 0 | H19: =R19-AB19 -> 0 | I19: =S19-AC19 -> 0 | J19: =T19-AD19 -> 0 | K19: =U19-AE19 -> 0
B20: G&A | C20: (000) | D20: =N20-X20 -> 0 | E20: =O20-Y20 -> 0 | F20: =P20-Z20 -> 0 | G20: =Q20-AA20 -> 0 | H20: =R20-AB20 -> 0 | I20: =S20-AC20 -> 0 | J20: =T20-AD20 -> 0 | K20: =U20-AE20 -> 0
B21: All Other Period Expenses | C21: (000) | D21: =N21-X21 -> 0 | E21: =O21-Y21 -> 0 | F21: =P21-Z21 -> 0 | G21: =Q21-AA21 -> 0 | H21: =R21-AB21 -> 0 | I21: =S21-AC21 -> 0 | J21: =T21-AD21 -> 0 | K21: =U21-AE21 -> 0
B22: Total Period Expenses | C22: (000) | D22: =N22-X22 -> 0 | E22: =O22-Y22 -> 0 | F22: =P22-Z22 -> 0 | G22: =Q22-AA22 -> 0 | H22: =R22-AB22 -> 0 | I22: =S22-AC22 -> 0 | J22: =T22-AD22 -> 0 | K22: =U22-AE22 -> 0
B23: Depreciation | C23: (000) | D23: =N23-X23 -> 0 | E23: =O23-Y23 -> 0 | F23: =P23-Z23 -> 0 | G23: =Q23-AA23 -> 0 | H23: =R23-AB23 -> 0 | I23: =S23-AC23 -> 0 | J23: =T23-AD23 -> 0 | K23: =U23-AE23 -> 0
B25: Operating Profit | C25: (000) | D25: =N25-X25 -> 0 | E25: =O25-Y25 -> 0 | F25: =P25-Z25 -> 0 | G25: =Q25-AA25 -> 0 | H25: =R25-AB25 -> 0 | I25: =S25-AC25 -> 0 | J25: =T25-AD25 -> 0 | K25: =U25-AE25 -> 0
B26: OP% | D26: =N26-X26 -> 0 | E26: =O26-Y26 -> 0 | F26: =P26-Z26 -> 0 | G26: =Q26-AA26 -> 0 | H26: =R26-AB26 -> 0 | I26: =S26-AC26 -> 0 | J26: =T26-AD26 -> 0 | K26: =U26-AE26 -> 0
B28: Non-Operating Expenses (Income) | C28: (000) | D28: =N28-X28 -> 0 | E28: =O28-Y28 -> 0 | F28: =P28-Z28 -> 0 | G28: =Q28-AA28 -> 0 | H28: =R28-AB28 -> 0 | I28: =S28-AC28 -> 0 | J28: =T28-AD28 -> 0 | K28: =U28-AE28 -> 0
B29: Investment Expenses | C29: (000) | D29: =N29-X29 -> 0 | E29: =O29-Y29 -> 0 | F29: =P29-Z29 -> 0 | G29: =Q29-AA29 -> 0 | H29: =R29-AB29 -> 0 | I29: =S29-AC29 -> 0 | J29: =T29-AD29 -> 0 | K29: =U29-AE29 -> 0
B30: Restructuring | C30: (000) | D30: =N30-X30 -> 0 | E30: =O30-Y30 -> 0 | F30: =P30-Z30 -> 0 | G30: =Q30-AA30 -> 0 | H30: =R30-AB30 -> 0 | I30: =S30-AC30 -> 0 | J30: =T30-AD30 -> 0 | K30: =U30-AE30 -> 0
B31: Taxes | C31: (000) | D31: =N31-X31 -> 0 | E31: =O31-Y31 -> 0 | F31: =P31-Z31 -> 0 | G31: =Q31-AA31 -> 0 | H31: =R31-AB31 -> 0 | I31: =S31-AC31 -> 0 | J31: =T31-AD31 -> 0 | K31: =U31-AE31 -> 0
B33: Net Income | C33: (000) | D33: =N33-X33 -> 0 | E33: =O33-Y33 -> 0 | F33: =P33-Z33 -> 0 | G33: =Q33-AA33 -> 0 | H33: =R33-AB33 -> 0 | I33: =S33-AC33 -> 0 | J33: =T33-AD33 -> 0 | K33: =U33-AE33 -> 0
D34: =N34-X34 -> 0 | E34: =O34-Y34 -> 0 | F34: =P34-Z34 -> 0 | G34: =Q34-AA34 -> 0 | H34: =R34-AB34 -> 0 | I34: =S34-AC34 -> 0 | J34: =T34-AD34 -> 0 | K34: =U34-AE34 -> 0
B36: Cash Flow Periodic | C36: (000) | D36: =N36-X36 -> 0 | E36: =O36-Y36 -> 0 | F36: =P36-Z36 -> 0 | G36: =Q36-AA36 -> 0 | H36: =R36-AB36 -> 0 | I36: =S36-AC36 -> 0 | J36: =T36-AD36 -> 0 | K36: =U36-AE36 -> 0
B37: Cash Flow Cumulative | C37: (000) | D37: =N37-X37 -> 0 | E37: =O37-Y37 -> 0 | F37: =P37-Z37 -> 0 | G37: =Q37-AA37 -> 0 | H37: =R37-AB37 -> 0 | I37: =S37-AC37 -> 0 | J37: =T37-AD37 -> 0 | K37: =U37-AE37 -> 0
B40: Working Capital Balance | C40: (000) | D40: =N40-X40 -> 0 | E40: =O40-Y40 -> 0 | F40: =P40-Z40 -> 0 | G40: =Q40-AA40 -> 0 | H40: =R40-AB40 -> 0 | I40: =S40-AC40 -> 0 | J40: =T40-AD40 -> 0 | K40: =U40-AE40 -> 0
B41: Change in Working Capital | C41: (000) | D41: =N41-X41 -> 0 | E41: =O41-Y41 -> 0 | F41: =P41-Z41 -> 0 | G41: =Q41-AA41 -> 0 | H41: =R41-AB41 -> 0 | I41: =S41-AC41 -> 0 | J41: =T41-AD41 -> 0 | K41: =U41-AE41 -> 0
B42: Total Investment | C42: (000) | D42: =N42-X42 -> 0 | E42: =O42-Y42 -> 0 | F42: =P42-Z42 -> 0 | G42: =Q42-AA42 -> 0 | H42: =R42-AB42 -> 0 | I42: =S42-AC42 -> 0 | J42: =T42-AD42 -> 0 | K42: =U42-AE42 -> 0
B43: ROIC (after-tax) | C43: pct. | D43: =IFERROR(D33/D42,0) -> 0 | E43: =IFERROR(E33/E42,0) -> 0 | F43: =IFERROR(F33/F42,0) -> 0 | G43: =IFERROR(G33/G42,0) -> 0 | H43: =IFERROR(H33/H42,0) -> 0 | I43: =IFERROR(I33/I42,0) -> 0 | J43: =IFERROR(J33/J42,0) -> 0 | K43: =IFERROR(K33/K42,0) -> 0
B45: Net Present Value | C45: (000) | D45: =NPV(wacc,G33:K33) -> 0
B46: Terminal Value | C46: (000) | D46: =(K33*(1+tv_growth)/(wacc-tv_growth))/(1+wacc)^5 -> 0
B47: Total EV | C47: (000) | D47: =SUM(D45:D46) -> 0
B49: Payback Period | C49: yrs | D49: {=IFERROR(MATCH(TRUE,G33:K33>=0,0),"5+")} -> 1

Sheet Scenarios
B2: =IF(Inputs!C4="","[Insert Project Name in Inputs Tab]",Inputs!C4) -> [Insert Project Name in Inputs Tab] | D2: Current State | M2: =Inputs!B22 -> Scenario 1 | V2: =Inputs!B23 -> Scenario 2 | AE2: =Inputs!B24 -> Scenario 3 | AN2: =Inputs!B25 -> Scenario 4 | AW2: =Inputs!B26 -> Scenario 5
B3: (000s) | D3: No Change - Only pulling actuals | M3: =Inputs!C22 -> Scenario 1 Description | V3: =Inputs!C23 -> Scenario 2 Description | AE3: =Inputs!C24 -> Scenario 3 Description | AN3: =Inputs!C25 -> Scenario 4 Description | AW3: =Inputs!C26 -> Scenario 5 Description
D5: 2023 | E5: 2024 | F5: 2025 | G5: 2026 | H5: 2027 | I5: 2028 | J5: 2029 | K5: 2030 | M5: 2023 | N5: 2024 | O5: 2025 | P5: 2026 | Q5: 2027 | R5: 2028 | S5: 2029 | T5: 2030 | V5: 2023 | W5: 2024 | X5: 2025 | Y5: 2026 | Z5: 2027 | AA5: 2028 | AB5: 2029 | AC5: 2030 | AE5: 2023 | AF5: 2024 | AG5: 2025 | AH5: 2026 | AI5: 2027 | AJ5: 2028 | AK5: 2029 | AL5: 2030 | AN5: 2023 | AO5: 2024 | AP5: 2025 | AQ5: 2026 | AR5: 2027 | AS5: 2028 | AT5: 2029 | AU5: 2030 | AW5: 2023 | AX5: 2024 | AY5: 2025 | AZ5: 2026 | BA5: 2027 | BB5: 2028 | BC5: 2029 | BD5: 2030
B6: Net Sales | C6: (000) | D6: ='1. Margins'!F519 -> 0 | E6: ='1. Margins'!G519 -> 0 | F6: ='1. Margins'!H519 -> 0 | G6: ='1. Margins'!M519 -> 0 | H6: ='1. Margins'!R519 -> 0 | I6: ='1. Margins'!S519 -> 0 | J6: ='1. Margins'!T519 -> 0 | K6: ='1. Margins'!U519 -> 0 | M6: ='1. Margins'!F19 -> 0 | N6: ='1. Margins'!G19 -> 0 | O6: ='1. Margins'!H19 -> 0 | P6: ='1. Margins'!M19 -> 0 | Q6: ='1. Margins'!R19 -> 0 | R6: ='1. Margins'!S19 -> 0 | S6: ='1. Margins'!T19 -> 0 | T6: ='1. Margins'!U19 -> 0 | V6: ='1. Margins'!F119 -> 0 | W6: ='1. Margins'!G119 -> 0 | X6: ='1. Margins'!H119 -> 0 | Y6: ='1. Margins'!M119 -> 0 | Z6: ='1. Margins'!R119 -> 0 | AA6: ='1. Margins'!S119 -> 0 | AB6: ='1. Margins'!T119 -> 0 | AC6: ='1. Margins'!U119 -> 0 | AE6: ='1. Margins'!F219 -> 0 | AF6: ='1. Margins'!G219 -> 0 | AG6: ='1. Margins'!H219 -> 0 | AH6: ='1. Margins'!M219 -> 0 | AI6: ='1. Margins'!R219 -> 0 | AJ6: ='1. Margins'!S219 -> 0 | AK6: ='1. Margins'!T219 -> 0 | AL6: ='1. Margins'!U219 -> 0 | AN6: ='1. Margins'!F319 -> 0 | AO6: ='1. Margins'!G319 -> 0 | AP6: ='1. Margins'!H319 -> 0 | AQ6: ='1. Margins'!M319 -> 0 | AR6: ='1. Margins'!R319 -> 0 | AS6: ='1. Margins'!S319 -> 0 | AT6: ='1. Margins'!T319 -> 0 | AU6: ='1. Margins'!U319 -> 0 | AW6: ='1. Margins'!F419 -> 0 | AX6: ='1. Margins'!G419 -> 0 | AY6: ='1. Margins'!H419 -> 0 | AZ6: ='1. Margins'!M419 -> 0 | BA6: ='1. Margins'!R419 -> 0 | BB6: ='1. Margins'!S419 -> 0 | BC6: ='1. Margins'!T419 -> 0 | BD6: ='1. Margins'!U419 -> 0
B8: Direct Margin | C8: (000) | D8: ='1. Margins'!F583 -> 0 | E8: ='1. Margins'!G583 -> 0 | F8: ='1. Margins'!H583 -> 0 | G8: ='1. Margins'!M583 -> 0 | H8: ='1. Margins'!R583 -> 0 | I8: ='1. Margins'!S583 -> 0 | J8: ='1. Margins'!T583 -> 0 | K8: ='1. Margins'!U583 -> 0 | M8: ='1. Margins'!F83 -> 0 | N8: ='1. Margins'!G83 -> 0 | O8: ='1. Margins'!H83 -> 0 | P8: ='1. Margins'!M83 -> 0 | Q8: ='1. Margins'!R83 -> 0 | R8: ='1. Margins'!S83 -> 0 | S8: ='1. Margins'!T83 -> 0 | T8: ='1. Margins'!U83 -> 0 | V8: ='1. Margins'!F183 -> 0 | W8: ='1. Margins'!G183 -> 0 | X8: ='1. Margins'!H183 -> 0 | Y8: ='1. Margins'!M183 -> 0 | Z8: ='1. Margins'!R183 -> 0 | AA8: ='1. Margins'!S183 -> 0 | AB8: ='1. Margins'!T183 -> 0 | AC8: ='1. Margins'!U183 -> 0 | AE8: ='1. Margins'!F283 -> 0 | AF8: ='1. Margins'!G283 -> 0 | AG8: ='1. Margins'!H283 -> 0 | AH8: ='1. Margins'!M283 -> 0 | AI8: ='1. Margins'!R283 -> 0 | AJ8: ='1. Margins'!S283 -> 0 | AK8: ='1. Margins'!T283 -> 0 | AL8: ='1. Margins'!U283 -> 0 | AN8: ='1. Margins'!F383 -> 0 | AO8: ='1. Margins'!G383 -> 0 | AP8: ='1. Margins'!H383 -> 0 | AQ8: ='1. Margins'!M383 -> 0 | AR8: ='1. Margins'!R383 -> 0 | AS8: ='1. Margins'!S383 -> 0 | AT8: ='1. Margins'!T383 -> 0 | AU8: ='1. Margins'!U383 -> 0 | AW8: ='1. Margins'!F483 -> 0 | AX8: ='1. Margins'!G483 -> 0 | AY8: ='1. Margins'!H483 -> 0 | AZ8: ='1. Margins'!M483 -> 0 | BA8: ='1. Margins'!R483 -> 0 | BB8: ='1. Margins'!S483 -> 0 | BC8: ='1. Margins'!T483 -> 0 | BD8: ='1. Margins'!U483 -> 0
B9: Direct Margin % | D9: =IFERROR(D8/D$6,0) -> 0 | E9: =IFERROR(E8/E$6,0) -> 0 | F9: =IFERROR(F8/F$6,0) -> 0 | G9: =IFERROR(G8/G$6,0) -> 0 | H9: =IFERROR(H8/H$6,0) -> 0 | I9: =IFERROR(I8/I$6,0) -> 0 | J9: =IFERROR(J8/J$6,0) -> 0 | K9: =IFERROR(K8/K$6,0) -> 0 | M9: =IFERROR(M8/M$6,0) -> 0 | N9: =IFERROR(N8/N$6,0) -> 0 | O9: =IFERROR(O8/O$6,0) -> 0 | P9: =IFERROR(P8/P$6,0) -> 0 | Q9: =IFERROR(Q8/Q$6,0) -> 0 | R9: =IFERROR(R8/R$6,0) -> 0 | S9: =IFERROR(S8/S$6,0) -> 0 | T9: =IFERROR(T8/T$6,0) -> 0 | V9: =IFERROR(V8/V$6,0) -> 0 | W9: =IFERROR(W8/W$6,0) -> 0 | X9: =IFERROR(X8/X$6,0) -> 0 | Y9: =IFERROR(Y8/Y$6,0) -> 0 | Z9: =IFERROR(Z8/Z$6,0) -> 0 | AA9: =IFERROR(AA8/AA$6,0) -> 0 | AB9: =IFERROR(AB8/AB$6,0) -> 0 | AC9: =IFERROR(AC8/AC$6,0) -> 0 | AE9: =IFERROR(AE8/AE$6,0) -> 0 | AF9: =IFERROR(AF8/AF$6,0) -> 0 | AG9: =IFERROR(AG8/AG$6,0) -> 0 | AH9: =IFERROR(AH8/AH$6,0) -> 0 | AI9: =IFERROR(AI8/AI$6,0) -> 0 | AJ9: =IFERROR(AJ8/AJ$6,0) -> 0 | AK9: =IFERROR(AK8/AK$6,0) -> 0 | AL9: =IFERROR(AL8/AL$6,0) -> 0 | AN9: =IFERROR(AN8/AN$6,0) -> 0 | AO9: =IFERROR(AO8/AO$6,0) -> 0 | AP9: =IFERROR(AP8/AP$6,0) -> 0 | AQ9: =IFERROR(AQ8/AQ$6,0) -> 0 | AR9: =IFERROR(AR8/AR$6,0) -> 0 | AS9: =IFERROR(AS8/AS$6,0) -> 0 | AT9: =IFERROR(AT8/AT$6,0) -> 0 | AU9: =IFERROR(AU8/AU$6,0) -> 0 | AW9: =IFERROR(AW8/AW$6,0) -> 0 | AX9: =IFERROR(AX8/AX$6,0) -> 0 | AY9: =IFERROR(AY8/AY$6,0) -> 0 | AZ9: =IFERROR(AZ8/AZ$6,0) -> 0 | BA9: =IFERROR(BA8/BA$6,0) -> 0 | BB9: =IFERROR(BB8/BB$6,0) -> 0 | BC9: =IFERROR(BC8/BC$6,0) -> 0 | BD9: =IFERROR(BD8/BD$6,0) -> 0
B11: Variances | C11: (000) | D11: ='2. OHCOGS'!F210 -> 0 | E11: ='2. OHCOGS'!G210 -> 0 | F11: ='2. OHCOGS'!H210 -> 0 | G11: ='2. OHCOGS'!M210 -> 0 | H11: ='2. OHCOGS'!R210 -> 0 | I11: ='2. OHCOGS'!S210 -> 0 | J11: ='2. OHCOGS'!T210 -> 0 | K11: ='2. OHCOGS'!U210 -> 0 | M11: ='2. OHCOGS'!F20 -> 0 | N11: ='2. OHCOGS'!G20 -> 0 | O11: ='2. OHCOGS'!H20 -> 0 | P11: ='2. OHCOGS'!M20 -> 0 | Q11: ='2. OHCOGS'!R20 -> 0 | R11: ='2. OHCOGS'!S20 -> 0 | S11: ='2. OHCOGS'!T20 -> 0 | T11: ='2. OHCOGS'!U20 -> 0 | V11: ='2. OHCOGS'!F58 -> 0 | W11: ='2. OHCOGS'!G58 -> 0 | X11: ='2. OHCOGS'!H58 -> 0 | Y11: ='2. OHCOGS'!M58 -> 0 | Z11: ='2. OHCOGS'!R58 -> 0 | AA11: ='2. OHCOGS'!S58 -> 0 | AB11: ='2. OHCOGS'!T58 -> 0 | AC11: ='2. OHCOGS'!U58 -> 0 | AE11: ='2. OHCOGS'!F96 -> 0 | AF11: ='2. OHCOGS'!G96 -> 0 | AG11: ='2. OHCOGS'!H96 -> 0 | AH11: ='2. OHCOGS'!M96 -> 0 | AI11: ='2. OHCOGS'!R96 -> 0 | AJ11: ='2. OHCOGS'!S96 -> 0 | AK11: ='2. OHCOGS'!T96 -> 0 | AL11: ='2. OHCOGS'!U96 -> 0 | AN11: ='2. OHCOGS'!F134 -> 0 | AO11: ='2. OHCOGS'!G134 -> 0 | AP11: ='2. OHCOGS'!H134 -> 0 | AQ11: ='2. OHCOGS'!M134 -> 0 | AR11: ='2. OHCOGS'!R134 -> 0 | AS11: ='2. OHCOGS'!S134 -> 0 | AT11: ='2. OHCOGS'!T134 -> 0 | AU11: ='2. OHCOGS'!U134 -> 0 | AW11: ='2. OHCOGS'!F172 -> 0 | AX11: ='2. OHCOGS'!G172 -> 0 | AY11: ='2. OHCOGS'!H172 -> 0 | AZ11: ='2. OHCOGS'!M172 -> 0 | BA11: ='2. OHCOGS'!R172 -> 0 | BB11: ='2. OHCOGS'!S172 -> 0 | BC11: ='2. OHCOGS'!T172 -> 0 | BD11: ='2. OHCOGS'!U172 -> 0
B12: OHCOGS | C12: (000) | D12: ='2. OHCOGS'!F223 -> 0 | E12: ='2. OHCOGS'!G223 -> 0 | F12: ='2. OHCOGS'!H223 -> 0 | G12: ='2. OHCOGS'!M223 -> 0 | H12: ='2. OHCOGS'!R223 -> 0 | I12: ='2. OHCOGS'!S223 -> 0 | J12: ='2. OHCOGS'!T223 -> 0 | K12: ='2. OHCOGS'!U223 -> 0 | M12: ='2. OHCOGS'!F37 -> 0 | N12: ='2. OHCOGS'!G37 -> 0 | O12: ='2. OHCOGS'!H37 -> 0 | P12: ='2. OHCOGS'!M37 -> 0 | Q12: ='2. OHCOGS'!R37 -> 0 | R12: ='2. OHCOGS'!S37 -> 0 | S12: ='2. OHCOGS'!T37 -> 0 | T12: ='2. OHCOGS'!U37 -> 0 | V12: ='2. OHCOGS'!F75 -> 0 | W12: ='2. OHCOGS'!G75 -> 0 | X12: ='2. OHCOGS'!H75 -> 0 | Y12: ='2. OHCOGS'!M75 -> 0 | Z12: ='2. OHCOGS'!R75 -> 0 | AA12: ='2. OHCOGS'!S75 -> 0 | AB12: ='2. OHCOGS'!T75 -> 0 | AC12: ='2. OHCOGS'!U75 -> 0 | AE12: ='2. OHCOGS'!F113 -> 0 | AF12: ='2. OHCOGS'!G113 -> 0 | AG12: ='2. OHCOGS'!H113 -> 0 | AH12: ='2. OHCOGS'!M113 -> 0 | AI12: ='2. OHCOGS'!R113 -> 0 | AJ12: ='2. OHCOGS'!S113 -> 0 | AK12: ='2. OHCOGS'!T113 -> 0 | AL12: ='2. OHCOGS'!U113 -> 0 | AN12: ='2. OHCOGS'!F151 -> 0 | AO12: ='2. OHCOGS'!G151 -> 0 | AP12: ='2. OHCOGS'!H151 -> 0 | AQ12: ='2. OHCOGS'!M151 -> 0 | AR12: ='2. OHCOGS'!R151 -> 0 | AS12: ='2. OHCOGS'!S151 -> 0 | AT12: ='2. OHCOGS'!T151 -> 0 | AU12: ='2. OHCOGS'!U151 -> 0 | AW12: ='2. OHCOGS'!F189 -> 0 | AX12: ='2. OHCOGS'!G189 -> 0 | AY12: ='2. OHCOGS'!H189 -> 0 | AZ12: ='2. OHCOGS'!M189 -> 0 | BA12: ='2. OHCOGS'!R189 -> 0 | BB12: ='2. OHCOGS'!S189 -> 0 | BC12: ='2. OHCOGS'!T189 -> 0 | BD12: ='2. OHCOGS'!U189 -> 0
B14: Gross Profit | C14: (000) | D14: =D8-SUM(D11:D12) -> 0 | E14: =E8-SUM(E11:E12) -> 0 | F14: =F8-SUM(F11:F12) -> 0 | G14: =G8-SUM(G11:G12) -> 0 | H14: =H8-SUM(H11:H12) -> 0 | I14: =I8-SUM(I11:I12) -> 0 | J14: =J8-SUM(J11:J12) -> 0 | K14: =K8-SUM(K11:K12) -> 0 | M14: =M8-SUM(M11:M12) -> 0 | N14: =N8-SUM(N11:N12) -> 0 | O14: =O8-SUM(O11:O12) -> 0 | P14: =P8-SUM(P11:P12) -> 0 | Q14: =Q8-SUM(Q11:Q12) -> 0 | R14: =R8-SUM(R11:R12) -> 0 | S14: =S8-SUM(S11:S12) -> 0 | T14: =T8-SUM(T11:T12) -> 0 | V14: =V8-SUM(V11:V12) -> 0 | W14: =W8-SUM(W11:W12) -> 0 | X14: =X8-SUM(X11:X12) -> 0 | Y14: =Y8-SUM(Y11:Y12) -> 0 | Z14: =Z8-SUM(Z11:Z12) -> 0 | AA14: =AA8-SUM(AA11:AA12) -> 0 | AB14: =AB8-SUM(AB11:AB12) -> 0 | AC14: =AC8-SUM(AC11:AC12) -> 0 | AE14: =AE8-SUM(AE11:AE12) -> 0 | AF14: =AF8-SUM(AF11:AF12) -> 0 | AG14: =AG8-SUM(AG11:AG12) -> 0 | AH14: =AH8-SUM(AH11:AH12) -> 0 | AI14: =AI8-SUM(AI11:AI12) -> 0 | AJ14: =AJ8-SUM(AJ11:AJ12) -> 0 | AK14: =AK8-SUM(AK11:AK12) -> 0 | AL14: =AL8-SUM(AL11:AL12) -> 0 | AN14: =AN8-SUM(AN11:AN12) -> 0 | AO14: =AO8-SUM(AO11:AO12) -> 0 | AP14: =AP8-SUM(AP11:AP12) -> 0 | AQ14: =AQ8-SUM(AQ11:AQ12) -> 0 | AR14: =AR8-SUM(AR11:AR12) -> 0 | AS14: =AS8-SUM(AS11:AS12) -> 0 | AT14: =AT8-SUM(AT11:AT12) -> 0 | AU14: =AU8-SUM(AU11:AU12) -> 0 | AW14: =AW8-SUM(AW11:AW12) -> 0 | AX14: =AX8-SUM(AX11:AX12) -> 0 | AY14: =AY8-SUM(AY11:AY12) -> 0 | AZ14: =AZ8-SUM(AZ11:AZ12) -> 0 | BA14: =BA8-SUM(BA11:BA12) -> 0 | BB14: =BB8-SUM(BB11:BB12) -> 0 | BC14: =BC8-SUM(BC11:BC12) -> 0 | BD14: =BD8-SUM(BD11:BD12) -> 0
B15: Gross Profit % | D15: =IFERROR(D14/D$6,0) -> 0 | E15: =IFERROR(E14/E$6,0) -> 0 | F15: =IFERROR(F14/F$6,0) -> 0 | G15: =IFERROR(G14/G$6,0) -> 0 | H15: =IFERROR(H14/H$6,0) -> 0 | I15: =IFERROR(I14/I$6,0) -> 0 | J15: =IFERROR(J14/J$6,0) -> 0 | K15: =IFERROR(K14/K$6,0) -> 0 | M15: =IFERROR(M14/M$6,0) -> 0 | N15: =IFERROR(N14/N$6,0) -> 0 | O15: =IFERROR(O14/O$6,0) -> 0 | P15: =IFERROR(P14/P$6,0) -> 0 | Q15: =IFERROR(Q14/Q$6,0) -> 0 | R15: =IFERROR(R14/R$6,0) -> 0 | S15: =IFERROR(S14/S$6,0) -> 0 | T15: =IFERROR(T14/T$6,0) -> 0 | V15: =IFERROR(V14/V$6,0) -> 0 | W15: =IFERROR(W14/W$6,0) -> 0 | X15: =IFERROR(X14/X$6,0) -> 0 | Y15: =IFERROR(Y14/Y$6,0) -> 0 | Z15: =IFERROR(Z14/Z$6,0) -> 0 | AA15: =IFERROR(AA14/AA$6,0) -> 0 | AB15: =IFERROR(AB14/AB$6,0) -> 0 | AC15: =IFERROR(AC14/AC$6,0) -> 0 | AE15: =IFERROR(AE14/AE$6,0) -> 0 | AF15: =IFERROR(AF14/AF$6,0) -> 0 | AG15: =IFERROR(AG14/AG$6,0) -> 0 | AH15: =IFERROR(AH14/AH$6,0) -> 0 | AI15: =IFERROR(AI14/AI$6,0) -> 0 | AJ15: =IFERROR(AJ14/AJ$6,0) -> 0 | AK15: =IFERROR(AK14/AK$6,0) -> 0 | AL15: =IFERROR(AL14/AL$6,0) -> 0 | AN15: =IFERROR(AN14/AN$6,0) -> 0 | AO15: =IFERROR(AO14/AO$6,0) -> 0 | AP15: =IFERROR(AP14/AP$6,0) -> 0 | AQ15: =IFERROR(AQ14/AQ$6,0) -> 0 | AR15: =IFERROR(AR14/AR$6,0) -> 0 | AS15: =IFERROR(AS14/AS$6,0) -> 0 | AT15: =IFERROR(AT14/AT$6,0) -> 0 | AU15: =IFERROR(AU14/AU$6,0) -> 0 | AW15: =IFERROR(AW14/AW$6,0) -> 0 | AX15: =IFERROR(AX14/AX$6,0) -> 0 | AY15: =IFERROR(AY14/AY$6,0) -> 0 | AZ15: =IFERROR(AZ14/AZ$6,0) -> 0 | BA15: =IFERROR(BA14/BA$6,0) -> 0 | BB15: =IFERROR(BB14/BB$6,0) -> 0 | BC15: =IFERROR(BC14/BC$6,0) -> 0 | BD15: =IFERROR(BD14/BD$6,0) -> 0
B17: R&D | C17: (000) | D17: ='3. Opex'!F132 -> 0 | E17: ='3. Opex'!G132 -> 0 | F17: ='3. Opex'!H132 -> 0 | G17: ='3. Opex'!M132 -> 0 | H17: ='3. Opex'!R132 -> 0 | I17: ='3. Opex'!S132 -> 0 | J17: ='3. Opex'!T132 -> 0 | K17: ='3. Opex'!U132 -> 0 | M17: ='3. Opex'!F12 -> 0 | N17: ='3. Opex'!G12 -> 0 | O17: ='3. Opex'!H12 -> 0 | P17: ='3. Opex'!M12 -> 0 | Q17: ='3. Opex'!R12 -> 0 | R17: ='3. Opex'!S12 -> 0 | S17: ='3. Opex'!T12 -> 0 | T17: ='3. Opex'!U12 -> 0 | V17: ='3. Opex'!F36 -> 0 | W17: ='3. Opex'!G36 -> 0 | X17: ='3. Opex'!H36 -> 0 | Y17: ='3. Opex'!M36 -> 0 | Z17: ='3. Opex'!R36 -> 0 | AA17: ='3. Opex'!S36 -> 0 | AB17: ='3. Opex'!T36 -> 0 | AC17: ='3. Opex'!U36 -> 0 | AE17: ='3. Opex'!F60 -> 0 | AF17: ='3. Opex'!G60 -> 0 | AG17: ='3. Opex'!H60 -> 0 | AH17: ='3. Opex'!M60 -> 0 | AI17: ='3. Opex'!R60 -> 0 | AJ17: ='3. Opex'!S60 -> 0 | AK17: ='3. Opex'!T60 -> 0 | AL17: ='3. Opex'!U60 -> 0 | AN17: ='3. Opex'!F84 -> 0 | AO17: ='3. Opex'!G84 -> 0 | AP17: ='3. Opex'!H84 -> 0 | AQ17: ='3. Opex'!M84 -> 0 | AR17: ='3. Opex'!R84 -> 0 | AS17: ='3. Opex'!S84 -> 0 | AT17: ='3. Opex'!T84 -> 0 | AU17: ='3. Opex'!U84 -> 0 | AW17: ='3. Opex'!F108 -> 0 | AX17: ='3. Opex'!G108 -> 0 | AY17: ='3. Opex'!H108 -> 0 | AZ17: ='3. Opex'!M108 -> 0 | BA17: ='3. Opex'!R108 -> 0 | BB17: ='3. Opex'!S108 -> 0 | BC17: ='3. Opex'!T108 -> 0 | BD17: ='3. Opex'!U108 -> 0
B18: S&M | C18: (000) | D18: =SUM('3. Opex'!F133:F134) -> 0 | E18: =SUM('3. Opex'!G133:G134) -> 0 | F18: =SUM('3. Opex'!H133:H134) -> 0 | G18: =SUM('3. Opex'!M133:M134) -> 0 | H18: =SUM('3. Opex'!R133:R134) -> 0 | I18: =SUM('3. Opex'!S133:S134) -> 0 | J18: =SUM('3. Opex'!T133:T134) -> 0 | K18: =SUM('3. Opex'!U133:U134) -> 0 | M18: =SUM('3. Opex'!F13:F14) -> 0 | N18: =SUM('3. Opex'!G13:G14) -> 0 | O18: =SUM('3. Opex'!H13:H14) -> 0 | P18: =SUM('3. Opex'!M13:M14) -> 0 | Q18: =SUM('3. Opex'!R13:R14) -> 0 | R18: =SUM('3. Opex'!S13:S14) -> 0 | S18: =SUM('3. Opex'!T13:T14) -> 0 | T18: =SUM('3. Opex'!U13:U14) -> 0 | V18: =SUM('3. Opex'!F37:F38) -> 0 | W18: =SUM('3. Opex'!G37:G38) -> 0 | X18: =SUM('3. Opex'!H37:H38) -> 0 | Y18: =SUM('3. Opex'!M37:M38) -> 0 | Z18: =SUM('3. Opex'!R37:R38) -> 0 | AA18: =SUM('3. Opex'!S37:S38) -> 0 | AB18: =SUM('3. Opex'!T37:T38) -> 0 | AC18: =SUM('3. Opex'!U37:U38) -> 0 | AE18: =SUM('3. Opex'!F61:F62) -> 0 | AF18: =SUM('3. Opex'!G61:G62) -> 0 | AG18: =SUM('3. Opex'!H61:H62) -> 0 | AH18: =SUM('3. Opex'!M61:M62) -> 0 | AI18: =SUM('3. Opex'!R61:R62) -> 0 | AJ18: =SUM('3. Opex'!S61:S62) -> 0 | AK18: =SUM('3. Opex'!T61:T62) -> 0 | AL18: =SUM('3. Opex'!U61:U62) -> 0 | AN18: =SUM('3. Opex'!F85:F86) -> 0 | AO18: =SUM('3. Opex'!G85:G86) -> 0 | AP18: =SUM('3. Opex'!H85:H86) -> 0 | AQ18: =SUM('3. Opex'!M85:M86) -> 0 | AR18: =SUM('3. Opex'!R85:R86) -> 0 | AS18: =SUM('3. Opex'!S85:S86) -> 0 | AT18: =SUM('3. Opex'!T85:T86) -> 0 | AU18: =SUM('3. Opex'!U85:U86) -> 0 | AW18: =SUM('3. Opex'!F109:F110) -> 0 | AX18: =SUM('3. Opex'!G109:G110) -> 0 | AY18: =SUM('3. Opex'!H109:H110) -> 0 | AZ18: =SUM('3. Opex'!M109:M110) -> 0 | BA18: =SUM('3. Opex'!R109:R110) -> 0 | BB18: =SUM('3. Opex'!S109:S110) -> 0 | BC18: =SUM('3. Opex'!T109:T110) -> 0 | BD18: =SUM('3. Opex'!U109:U110) -> 0
B19: G&A | C19: (000) | D19: =SUM('3. Opex'!F135:F139) -> 0 | E19: =SUM('3. Opex'!G135:G139) -> 0 | F19: =SUM('3. Opex'!H135:H139) -> 0 | G19: =SUM('3. Opex'!M135:M139) -> 0 | H19: =SUM('3. Opex'!R135:R139) -> 0 | I19: =SUM('3. Opex'!S135:S139) -> 0 | J19: =SUM('3. Opex'!T135:T139) -> 0 | K19: =SUM('3. Opex'!U135:U139) -> 0 | M19: =SUM('3. Opex'!F15:F19) -> 0 | N19: =SUM('3. Opex'!G15:G19) -> 0 | O19: =SUM('3. Opex'!H15:H19) -> 0 | P19: =SUM('3. Opex'!M15:M19) -> 0 | Q19: =SUM('3. Opex'!R15:R19) -> 0 | R19: =SUM('3. Opex'!S15:S19) -> 0 | S19: =SUM('3. Opex'!T15:T19) -> 0 | T19: =SUM('3. Opex'!U15:U19) -> 0 | V19: =SUM('3. Opex'!F39:F43) -> 0 | W19: =SUM('3. Opex'!G39:G43) -> 0 | X19: =SUM('3. Opex'!H39:H43) -> 0 | Y19: =SUM('3. Opex'!M39:M43) -> 0 | Z19: =SUM('3. Opex'!R39:R43) -> 0 | AA19: =SUM('3. Opex'!S39:S43) -> 0 | AB19: =SUM('3. Opex'!T39:T43) -> 0 | AC19: =SUM('3. Opex'!U39:U43) -> 0 | AE19: =SUM('3. Opex'!F63:F67) -> 0 | AF19: =SUM('3. Opex'!G63:G67) -> 0 | AG19: =SUM('3. Opex'!H63:H67) -> 0 | AH19: =SUM('3. Opex'!M63:M67) -> 0 | AI19: =SUM('3. Opex'!R63:R67) -> 0 | AJ19: =SUM('3. Opex'!S63:S67) -> 0 | AK19: =SUM('3. Opex'!T63:T67) -> 0 | AL19: =SUM('3. Opex'!U63:U67) -> 0 | AN19: =SUM('3. Opex'!F87:F91) -> 0 | AO19: =SUM('3. Opex'!G87:G91) -> 0 | AP19: =SUM('3. Opex'!H87:H91) -> 0 | AQ19: =SUM('3. Opex'!M87:M91) -> 0 | AR19: =SUM('3. Opex'!R87:R91) -> 0 | AS19: =SUM('3. Opex'!S87:S91) -> 0 | AT19: =SUM('3. Opex'!T87:T91) -> 0 | AU19: =SUM('3. Opex'!U87:U91) -> 0 | AW19: =SUM('3. Opex'!F111:F115) -> 0 | AX19: =SUM('3. Opex'!G111:G115) -> 0 | AY19: =SUM('3. Opex'!H111:H115) -> 0 | AZ19: =SUM('3. Opex'!M111:M115) -> 0 | BA19: =SUM('3. Opex'!R111:R115) -> 0 | BB19: =SUM('3. Opex'!S111:S115) -> 0 | BC19: =SUM('3. Opex'!T111:T115) -> 0 | BD19: =SUM('3. Opex'!U111:U115) -> 0
B20: All Other Period Expenses | C20: (000) | D20: =SUM('3. Opex'!F140:F142) -> 0 | E20: =SUM('3. Opex'!G140:G142) -> 0 | F20: =SUM('3. Opex'!H140:H142) -> 0 | G20: =SUM('3. Opex'!M140:M142) -> 0 | H20: =SUM('3. Opex'!R140:R142) -> 0 | I20: =SUM('3. Opex'!S140:S142) -> 0 | J20: =SUM('3. Opex'!T140:T142) -> 0 | K20: =SUM('3. Opex'!U140:U142) -> 0 | M20: =SUM('3. Opex'!F20:F22) -> 0 | N20: =SUM('3. Opex'!G20:G22) -> 0 | O20: =SUM('3. Opex'!H20:H22) -> 0 | P20: =SUM('3. Opex'!M20:M22) -> 0 | Q20: =SUM('3. Opex'!R20:R22) -> 0 | R20: =SUM('3. Opex'!S20:S22) -> 0 | S20: =SUM('3. Opex'!T20:T22) -> 0 | T20: =SUM('3. Opex'!U20:U22) -> 0 | V20: =SUM('3. Opex'!F44:F46) -> 0 | W20: =SUM('3. Opex'!G44:G46) -> 0 | X20: =SUM('3. Opex'!H44:H46) -> 0 | Y20: =SUM('3. Opex'!M44:M46) -> 0 | Z20: =SUM('3. Opex'!R44:R46) -> 0 | AA20: =SUM('3. Opex'!S44:S46) -> 0 | AB20: =SUM('3. Opex'!T44:T46) -> 0 | AC20: =SUM('3. Opex'!U44:U46) -> 0 | AE20: =SUM('3. Opex'!F68:F70) -> 0 | AF20: =SUM('3. Opex'!G68:G70) -> 0 | AG20: =SUM('3. Opex'!H68:H70) -> 0 | AH20: =SUM('3. Opex'!M68:M70) -> 0 | AI20: =SUM('3. Opex'!R68:R70) -> 0 | AJ20: =SUM('3. Opex'!S68:S70) -> 0 | AK20: =SUM('3. Opex'!T68:T70) -> 0 | AL20: =SUM('3. Opex'!U68:U70) -> 0 | AN20: =SUM('3. Opex'!F92:F94) -> 0 | AO20: =SUM('3. Opex'!G92:G94) -> 0 | AP20: =SUM('3. Opex'!H92:H94) -> 0 | AQ20: =SUM('3. Opex'!M92:M94) -> 0 | AR20: =SUM('3. Opex'!R92:R94) -> 0 | AS20: =SUM('3. Opex'!S92:S94) -> 0 | AT20: =SUM('3. Opex'!T92:T94) -> 0 | AU20: =SUM('3. Opex'!U92:U94) -> 0 | AW20: =SUM('3. Opex'!F116:F118) -> 0 | AX20: =SUM('3. Opex'!G116:G118) -> 0 | AY20: =SUM('3. Opex'!H116:H118) -> 0 | AZ20: =SUM('3. Opex'!M116:M118) -> 0 | BA20: =SUM('3. Opex'!R116:R118) -> 0 | BB20: =SUM('3. Opex'!S116:S118) -> 0 | BC20: =SUM('3. Opex'!T116:T118) -> 0 | BD20: =SUM('3. Opex'!U116:U118) -> 0
B21: Total Period Expenses | C21: (000) | D21: =SUM(D17:D20) -> 0 | E21: =SUM(E17:E20) -> 0 | F21: =SUM(F17:F20) -> 0 | G21: =SUM(G17:G20) -> 0 | H21: =SUM(H17:H20) -> 0 | I21: =SUM(I17:I20) -> 0 | J21: =SUM(J17:J20) -> 0 | K21: =SUM(K17:K20) -> 0 | M21: =SUM(M17:M20) -> 0 | N21: =SUM(N17:N20) -> 0 | O21: =SUM(O17:O20) -> 0 | P21: =SUM(P17:P20) -> 0 | Q21: =SUM(Q17:Q20) -> 0 | R21: =SUM(R17:R20) -> 0 | S21: =SUM(S17:S20) -> 0 | T21: =SUM(T17:T20) -> 0 | V21: =SUM(V17:V20) -> 0 | W21: =SUM(W17:W20) -> 0 | X21: =SUM(X17:X20) -> 0 | Y21: =SUM(Y17:Y20) -> 0 | Z21: =SUM(Z17:Z20) -> 0 | AA21: =SUM(AA17:AA20) -> 0 | AB21: =SUM(AB17:AB20) -> 0 | AC21: =SUM(AC17:AC20) -> 0 | AE21: =SUM(AE17:AE20) -> 0 | AF21: =SUM(AF17:AF20) -> 0 | AG21: =SUM(AG17:AG20) -> 0 | AH21: =SUM(AH17:AH20) -> 0 | AI21: =SUM(AI17:AI20) -> 0 | AJ21: =SUM(AJ17:AJ20) -> 0 | AK21: =SUM(AK17:AK20) -> 0 | AL21: =SUM(AL17:AL20) -> 0 | AN21: =SUM(AN17:AN20) -> 0 | AO21: =SUM(AO17:AO20) -> 0 | AP21: =SUM(AP17:AP20) -> 0 | AQ21: =SUM(AQ17:AQ20) -> 0 | AR21: =SUM(AR17:AR20) -> 0 | AS21: =SUM(AS17:AS20) -> 0 | AT21: =SUM(AT17:AT20) -> 0 | AU21: =SUM(AU17:AU20) -> 0 | AW21: =SUM(AW17:AW20) -> 0 | AX21: =SUM(AX17:AX20) -> 0 | AY21: =SUM(AY17:AY20) -> 0 | AZ21: =SUM(AZ17:AZ20) -> 0 | BA21: =SUM(BA17:BA20) -> 0 | BB21: =SUM(BB17:BB20) -> 0 | BC21: =SUM(BC17:BC20) -> 0 | BD21: =SUM(BD17:BD20) -> 0
B22: Depreciation | C22: (000) | D22: ='4. Investments'!F429 -> 0 | E22: ='4. Investments'!G429 -> 0 | F22: ='4. Investments'!H429 -> 0 | G22: ='4. Investments'!M429 -> 0 | H22: ='4. Investments'!R429 -> 0 | I22: ='4. Investments'!S429 -> 0 | J22: ='4. Investments'!T429 -> 0 | K22: ='4. Investments'!U429 -> 0 | M22: ='4. Investments'!F44 -> 0 | N22: ='4. Investments'!G44 -> 0 | O22: ='4. Investments'!H44 -> 0 | P22: ='4. Investments'!M44 -> 0 | Q22: ='4. Investments'!R44 -> 0 | R22: ='4. Investments'!S44 -> 0 | S22: ='4. Investments'!T44 -> 0 | T22: ='4. Investments'!U44 -> 0 | V22: ='4. Investments'!F121 -> 0 | W22: ='4. Investments'!G121 -> 0 | X22: ='4. Investments'!H121 -> 0 | Y22: ='4. Investments'!M121 -> 0 | Z22: ='4. Investments'!R121 -> 0 | AA22: ='4. Investments'!S121 -> 0 | AB22: ='4. Investments'!T121 -> 0 | AC22: ='4. Investments'!U121 -> 0 | AE22: ='4. Investments'!F198 -> 0 | AF22: ='4. Investments'!G198 -> 0 | AG22: ='4. Investments'!H198 -> 0 | AH22: ='4. Investments'!M198 -> 0 | AI22: ='4. Investments'!R198 -> 0 | AJ22: ='4. Investments'!S198 -> 0 | AK22: ='4. Investments'!T198 -> 0 | AL22: ='4. Investments'!U198 -> 0 | AN22: ='4. Investments'!F275 -> 0 | AO22: ='4. Investments'!G275 -> 0 | AP22: ='4. Investments'!H275 -> 0 | AQ22: ='4. Investments'!M275 -> 0 | AR22: ='4. Investments'!R275 -> 0 | AS22: ='4. Investments'!S275 -> 0 | AT22: ='4. Investments'!T275 -> 0 | AU22: ='4. Investments'!U275 -> 0 | AW22: ='4. Investments'!F352 -> 0 | AX22: ='4. Investments'!G352 -> 0 | AY22: ='4. Investments'!H352 -> 0 | AZ22: ='4. Investments'!M352 -> 0 | BA22: ='4. Investments'!R352 -> 0 | BB22: ='4. Investments'!S352 -> 0 | BC22: ='4. Investments'!T352 -> 0 | BD22: ='4. Investments'!U352 -> 0
B24: Operating Profit | C24: (000) | D24: =D14-D21-D22 -> 0 | E24: =E14-E21-E22 -> 0 | F24: =F14-F21-F22 -> 0 | G24: =G14-G21-G22 -> 0 | H24: =H14-H21-H22 -> 0 | I24: =I14-I21-I22 -> 0 | J24: =J14-J21-J22 -> 0 | K24: =K14-K21-K22 -> 0 | M24: =M14-M21-M22 -> 0 | N24: =N14-N21-N22 -> 0 | O24: =O14-O21-O22 -> 0 | P24: =P14-P21-P22 -> 0 | Q24: =Q14-Q21-Q22 -> 0 | R24: =R14-R21-R22 -> 0 | S24: =S14-S21-S22 -> 0 | T24: =T14-T21-T22 -> 0 | V24: =V14-V21-V22 -> 0 | W24: =W14-W21-W22 -> 0 | X24: =X14-X21-X22 -> 0 | Y24: =Y14-Y21-Y22 -> 0 | Z24: =Z14-Z21-Z22 -> 0 | AA24: =AA14-AA21-AA22 -> 0 | AB24: =AB14-AB21-AB22 -> 0 | AC24: =AC14-AC21-AC22 -> 0 | AE24: =AE14-AE21-AE22 -> 0 | AF24: =AF14-AF21-AF22 -> 0 | AG24: =AG14-AG21-AG22 -> 0 | AH24: =AH14-AH21-AH22 -> 0 | AI24: =AI14-AI21-AI22 -> 0 | AJ24: =AJ14-AJ21-AJ22 -> 0 | AK24: =AK14-AK21-AK22 -> 0 | AL24: =AL14-AL21-AL22 -> 0 | AN24: =AN14-AN21-AN22 -> 0 | AO24: =AO14-AO21-AO22 -> 0 | AP24: =AP14-AP21-AP22 -> 0 | AQ24: =AQ14-AQ21-AQ22 -> 0 | AR24: =AR14-AR21-AR22 -> 0 | AS24: =AS14-AS21-AS22 -> 0 | AT24: =AT14-AT21-AT22 -> 0 | AU24: =AU14-AU21-AU22 -> 0 | AW24: =AW14-AW21-AW22 -> 0 | AX24: =AX14-AX21-AX22 -> 0 | AY24: =AY14-AY21-AY22 -> 0 | AZ24: =AZ14-AZ21-AZ22 -> 0 | BA24: =BA14-BA21-BA22 -> 0 | BB24: =BB14-BB21-BB22 -> 0 | BC24: =BC14-BC21-BC22 -> 0 | BD24: =BD14-BD21-BD22 -> 0
B25: OP% | D25: =IFERROR(D24/D$6,0) -> 0 | E25: =IFERROR(E24/E$6,0) -> 0 | F25: =IFERROR(F24/F$6,0) -> 0 | G25: =IFERROR(G24/G$6,0) -> 0 | H25: =IFERROR(H24/H$6,0) -> 0 | I25: =IFERROR(I24/I$6,0) -> 0 | J25: =IFERROR(J24/J$6,0) -> 0 | K25: =IFERROR(K24/K$6,0) -> 0 | M25: =IFERROR(M24/M$6,0) -> 0 | N25: =IFERROR(N24/N$6,0) -> 0 | O25: =IFERROR(O24/O$6,0) -> 0 | P25: =IFERROR(P24/P$6,0) -> 0 | Q25: =IFERROR(Q24/Q$6,0) -> 0 | R25: =IFERROR(R24/R$6,0) -> 0 | S25: =IFERROR(S24/S$6,0) -> 0 | T25: =IFERROR(T24/T$6,0) -> 0 | V25: =IFERROR(V24/V$6,0) -> 0 | W25: =IFERROR(W24/W$6,0) -> 0 | X25: =IFERROR(X24/X$6,0) -> 0 | Y25: =IFERROR(Y24/Y$6,0) -> 0 | Z25: =IFERROR(Z24/Z$6,0) -> 0 | AA25: =IFERROR(AA24/AA$6,0) -> 0 | AB25: =IFERROR(AB24/AB$6,0) -> 0 | AC25: =IFERROR(AC24/AC$6,0) -> 0 | AE25: =IFERROR(AE24/AE$6,0) -> 0 | AF25: =IFERROR(AF24/AF$6,0) -> 0 | AG25: =IFERROR(AG24/AG$6,0) -> 0 | AH25: =IFERROR(AH24/AH$6,0) -> 0 | AI25: =IFERROR(AI24/AI$6,0) -> 0 | AJ25: =IFERROR(AJ24/AJ$6,0) -> 0 | AK25: =IFERROR(AK24/AK$6,0) -> 0 | AL25: =IFERROR(AL24/AL$6,0) -> 0 | AN25: =IFERROR(AN24/AN$6,0) -> 0 | AO25: =IFERROR(AO24/AO$6,0) -> 0 | AP25: =IFERROR(AP24/AP$6,0) -> 0 | AQ25: =IFERROR(AQ24/AQ$6,0) -> 0 | AR25: =IFERROR(AR24/AR$6,0) -> 0 | AS25: =IFERROR(AS24/AS$6,0) -> 0 | AT25: =IFERROR(AT24/AT$6,0) -> 0 | AU25: =IFERROR(AU24/AU$6,0) -> 0 | AW25: =IFERROR(AW24/AW$6,0) -> 0 | AX25: =IFERROR(AX24/AX$6,0) -> 0 | AY25: =IFERROR(AY24/AY$6,0) -> 0 | AZ25: =IFERROR(AZ24/AZ$6,0) -> 0 | BA25: =IFERROR(BA24/BA$6,0) -> 0 | BB25: =IFERROR(BB24/BB$6,0) -> 0 | BC25: =IFERROR(BC24/BC$6,0) -> 0 | BD25: =IFERROR(BD24/BD$6,0) -> 0
B27: Non-Operating Expenses (Income) | C27: (000) | D27: =SUM('7. Non-Opex'!F232,'7. Non-Opex'!F251) -> 0 | E27: =SUM('7. Non-Opex'!G232,'7. Non-Opex'!G251) -> 0 | F27: =SUM('7. Non-Opex'!H232,'7. Non-Opex'!H251) -> 0 | G27: =SUM('7. Non-Opex'!M232,'7. Non-Opex'!M251) -> 0 | H27: =SUM('7. Non-Opex'!R232,'7. Non-Opex'!R251) -> 0 | I27: =SUM('7. Non-Opex'!S232,'7. Non-Opex'!S251) -> 0 | J27: =SUM('7. Non-Opex'!T232,'7. Non-Opex'!T251) -> 0 | K27: =SUM('7. Non-Opex'!U232,'7. Non-Opex'!U251) -> 0 | M27: =SUM('7. Non-Opex'!F22,'7. Non-Opex'!F41) -> 0 | N27: =SUM('7. Non-Opex'!G22,'7. Non-Opex'!G41) -> 0 | O27: =SUM('7. Non-Opex'!H22,'7. Non-Opex'!H41) -> 0 | P27: =SUM('7. Non-Opex'!M22,'7. Non-Opex'!M41) -> 0 | Q27: =SUM('7. Non-Opex'!R22,'7. Non-Opex'!R41) -> 0 | R27: =SUM('7. Non-Opex'!S22,'7. Non-Opex'!S41) -> 0 | S27: =SUM('7. Non-Opex'!T22,'7. Non-Opex'!T41) -> 0 | T27: =SUM('7. Non-Opex'!U22,'7. Non-Opex'!U41) -> 0 | V27: =SUM('7. Non-Opex'!F64,'7. Non-Opex'!F83) -> 0 | W27: =SUM('7. Non-Opex'!G64,'7. Non-Opex'!G83) -> 0 | X27: =SUM('7. Non-Opex'!H64,'7. Non-Opex'!H83) -> 0 | Y27: =SUM('7. Non-Opex'!M64,'7. Non-Opex'!M83) -> 0 | Z27: =SUM('7. Non-Opex'!R64,'7. Non-Opex'!R83) -> 0 | AA27: =SUM('7. Non-Opex'!S64,'7. Non-Opex'!S83) -> 0 | AB27: =SUM('7. Non-Opex'!T64,'7. Non-Opex'!T83) -> 0 | AC27: =SUM('7. Non-Opex'!U64,'7. Non-Opex'!U83) -> 0 | AE27: =SUM('7. Non-Opex'!F106,'7. Non-Opex'!F125) -> 0 | AF27: =SUM('7. Non-Opex'!G106,'7. Non-Opex'!G125) -> 0 | AG27: =SUM('7. Non-Opex'!H106,'7. Non-Opex'!H125) -> 0 | AH27: =SUM('7. Non-Opex'!M106,'7. Non-Opex'!M125) -> 0 | AI27: =SUM('7. Non-Opex'!R106,'7. Non-Opex'!R125) -> 0 | AJ27: =SUM('7. Non-Opex'!S106,'7. Non-Opex'!S125) -> 0 | AK27: =SUM('7. Non-Opex'!T106,'7. Non-Opex'!T125) -> 0 | AL27: =SUM('7. Non-Opex'!U106,'7. Non-Opex'!U125) -> 0 | AN27: =SUM('7. Non-Opex'!F148,'7. Non-Opex'!F167) -> 0 | AO27: =SUM('7. Non-Opex'!G148,'7. Non-Opex'!G167) -> 0 | AP27: =SUM('7. Non-Opex'!H148,'7. Non-Opex'!H167) -> 0 | AQ27: =SUM('7. Non-Opex'!M148,'7. Non-Opex'!M167) -> 0 | AR27: =SUM('7. Non-Opex'!R148,'7. Non-Opex'!R167) -> 0 | AS27: =SUM('7. Non-Opex'!S148,'7. Non-Opex'!S167) -> 0 | AT27: =SUM('7. Non-Opex'!T148,'7. Non-Opex'!T167) -> 0 | AU27: =SUM('7. Non-Opex'!U148,'7. Non-Opex'!U167) -> 0 | AW27: =SUM('7. Non-Opex'!F190,'7. Non-Opex'!F209) -> 0 | AX27: =SUM('7. Non-Opex'!G190,'7. Non-Opex'!G209) -> 0 | AY27: =SUM('7. Non-Opex'!H190,'7. Non-Opex'!H209) -> 0 | AZ27: =SUM('7. Non-Opex'!M190,'7. Non-Opex'!M209) -> 0 | BA27: =SUM('7. Non-Opex'!R190,'7. Non-Opex'!R209) -> 0 | BB27: =SUM('7. Non-Opex'!S190,'7. Non-Opex'!S209) -> 0 | BC27: =SUM('7. Non-Opex'!T190,'7. Non-Opex'!T209) -> 0 | BD27: =SUM('7. Non-Opex'!U190,'7. Non-Opex'!U209) -> 0
B28: Investment Expenses | C28: (000) | D28: ='4. Investments'!F404 -> 0 | E28: ='4. Investments'!G404 -> 0 | F28: ='4. Investments'!H404 -> 0 | G28: ='4. Investments'!M404 -> 0 | H28: ='4. Investments'!R404 -> 0 | I28: ='4. Investments'!S404 -> 0 | J28: ='4. Investments'!T404 -> 0 | K28: ='4. Investments'!U404 -> 0 | M28: ='4. Investments'!F19 -> 0 | N28: ='4. Investments'!G19 -> 0 | O28: ='4. Investments'!H19 -> 0 | P28: ='4. Investments'!M19 -> 0 | Q28: ='4. Investments'!R19 -> 0 | R28: ='4. Investments'!S19 -> 0 | S28: ='4. Investments'!T19 -> 0 | T28: ='4. Investments'!U19 -> 0 | V28: ='4. Investments'!F96 -> 0 | W28: ='4. Investments'!G96 -> 0 | X28: ='4. Investments'!H96 -> 0 | Y28: ='4. Investments'!M96 -> 0 | Z28: ='4. Investments'!R96 -> 0 | AA28: ='4. Investments'!S96 -> 0 | AB28: ='4. Investments'!T96 -> 0 | AC28: ='4. Investments'!U96 -> 0 | AE28: ='4. Investments'!F173 -> 0 | AF28: ='4. Investments'!G173 -> 0 | AG28: ='4. Investments'!H173 -> 0 | AH28: ='4. Investments'!M173 -> 0 | AI28: ='4. Investments'!R173 -> 0 | AJ28: ='4. Investments'!S173 -> 0 | AK28: ='4. Investments'!T173 -> 0 | AL28: ='4. Investments'!U173 -> 0 | AN28: ='4. Investments'!F250 -> 0 | AO28: ='4. Investments'!G250 -> 0 | AP28: ='4. Investments'!H250 -> 0 | AQ28: ='4. Investments'!M250 -> 0 | AR28: ='4. Investments'!R250 -> 0 | AS28: ='4. Investments'!S250 -> 0 | AT28: ='4. Investments'!T250 -> 0 | AU28: ='4. Investments'!U250 -> 0 | AW28: ='4. Investments'!F327 -> 0 | AX28: ='4. Investments'!G327 -> 0 | AY28: ='4. Investments'!H327 -> 0 | AZ28: ='4. Investments'!M327 -> 0 | BA28: ='4. Investments'!R327 -> 0 | BB28: ='4. Investments'!S327 -> 0 | BC28: ='4. Investments'!T327 -> 0 | BD28: ='4. Investments'!U327 -> 0
B29: Restructuring | C29: (000) | D29: ='4. Investments'!F461 -> 0 | E29: ='4. Investments'!G461 -> 0 | F29: ='4. Investments'!H461 -> 0 | G29: ='4. Investments'!M461 -> 0 | H29: ='4. Investments'!R461 -> 0 | I29: ='4. Investments'!S461 -> 0 | J29: ='4. Investments'!T461 -> 0 | K29: ='4. Investments'!U461 -> 0 | M29: ='4. Investments'!F76 -> 0 | N29: ='4. Investments'!G76 -> 0 | O29: ='4. Investments'!H76 -> 0 | P29: ='4. Investments'!M76 -> 0 | Q29: ='4. Investments'!R76 -> 0 | R29: ='4. Investments'!S76 -> 0 | S29: ='4. Investments'!T76 -> 0 | T29: ='4. Investments'!U76 -> 0 | V29: ='4. Investments'!F153 -> 0 | W29: ='4. Investments'!G153 -> 0 | X29: ='4. Investments'!H153 -> 0 | Y29: ='4. Investments'!M153 -> 0 | Z29: ='4. Investments'!R153 -> 0 | AA29: ='4. Investments'!S153 -> 0 | AB29: ='4. Investments'!T153 -> 0 | AC29: ='4. Investments'!U153 -> 0 | AE29: ='4. Investments'!F230 -> 0 | AF29: ='4. Investments'!G230 -> 0 | AG29: ='4. Investments'!H230 -> 0 | AH29: ='4. Investments'!M230 -> 0 | AI29: ='4. Investments'!R230 -> 0 | AJ29: ='4. Investments'!S230 -> 0 | AK29: ='4. Investments'!T230 -> 0 | AL29: ='4. Investments'!U230 -> 0 | AN29: ='4. Investments'!F307 -> 0 | AO29: ='4. Investments'!G307 -> 0 | AP29: ='4. Investments'!H307 -> 0 | AQ29: ='4. Investments'!M307 -> 0 | AR29: ='4. Investments'!R307 -> 0 | AS29: ='4. Investments'!S307 -> 0 | AT29: ='4. Investments'!T307 -> 0 | AU29: ='4. Investments'!U307 -> 0 | AW29: ='4. Investments'!F384 -> 0 | AX29: ='4. Investments'!G384 -> 0 | AY29: ='4. Investments'!H384 -> 0 | AZ29: ='4. Investments'!M384 -> 0 | BA29: ='4. Investments'!R384 -> 0 | BB29: ='4. Investments'!S384 -> 0 | BC29: ='4. Investments'!T384 -> 0 | BD29: ='4. Investments'!U384 -> 0
B30: Taxes | C30: (000) | D30: ='6. Tax'!F137 -> 0 | E30: ='6. Tax'!G137 -> 0 | F30: ='6. Tax'!H137 -> 0 | G30: ='6. Tax'!M137 -> 0 | H30: ='6. Tax'!R137 -> 0 | I30: ='6. Tax'!S137 -> 0 | J30: ='6. Tax'!T137 -> 0 | K30: ='6. Tax'!U137 -> 0 | M30: ='6. Tax'!F22 -> 0 | N30: ='6. Tax'!G22 -> 0 | O30: ='6. Tax'!H22 -> 0 | P30: ='6. Tax'!M22 -> 0 | Q30: ='6. Tax'!R22 -> 0 | R30: ='6. Tax'!S22 -> 0 | S30: ='6. Tax'!T22 -> 0 | T30: ='6. Tax'!U22 -> 0 | V30: ='6. Tax'!F45 -> 0 | W30: ='6. Tax'!G45 -> 0 | X30: ='6. Tax'!H45 -> 0 | Y30: ='6. Tax'!M45 -> 0 | Z30: ='6. Tax'!R45 -> 0 | AA30: ='6. Tax'!S45 -> 0 | AB30: ='6. Tax'!T45 -> 0 | AC30: ='6. Tax'!U45 -> 0 | AE30: ='6. Tax'!F68 -> 0 | AF30: ='6. Tax'!G68 -> 0 | AG30: ='6. Tax'!H68 -> 0 | AH30: ='6. Tax'!M68 -> 0 | AI30: ='6. Tax'!R68 -> 0 | AJ30: ='6. Tax'!S68 -> 0 | AK30: ='6. Tax'!T68 -> 0 | AL30: ='6. Tax'!U68 -> 0 | AN30: ='6. Tax'!F91 -> 0 | AO30: ='6. Tax'!G91 -> 0 | AP30: ='6. Tax'!H91 -> 0 | AQ30: ='6. Tax'!M91 -> 0 | AR30: ='6. Tax'!R91 -> 0 | AS30: ='6. Tax'!S91 -> 0 | AT30: ='6. Tax'!T91 -> 0 | AU30: ='6. Tax'!U91 -> 0 | AW30: ='6. Tax'!F114 -> 0 | AX30: ='6. Tax'!G114 -> 0 | AY30: ='6. Tax'!H114 -> 0 | AZ30: ='6. Tax'!M114 -> 0 | BA30: ='6. Tax'!R114 -> 0 | BB30: ='6. Tax'!S114 -> 0 | BC30: ='6. Tax'!T114 -> 0 | BD30: ='6. Tax'!U114 -> 0
B32: Net Income | C32: (000) | D32: =D24-SUM(D27:D30) -> 0 | E32: =E24-SUM(E27:E30) -> 0 | F32: =F24-SUM(F27:F30) -> 0 | G32: =G24-SUM(G27:G30) -> 0 | H32: =H24-SUM(H27:H30) -> 0 | I32: =I24-SUM(I27:I30) -> 0 | J32: =J24-SUM(J27:J30) -> 0 | K32: =K24-SUM(K27:K30) -> 0 | M32: =M24-SUM(M27:M30) -> 0 | N32: =N24-SUM(N27:N30) -> 0 | O32: =O24-SUM(O27:O30) -> 0 | P32: =P24-SUM(P27:P30) -> 0 | Q32: =Q24-SUM(Q27:Q30) -> 0 | R32: =R24-SUM(R27:R30) -> 0 | S32: =S24-SUM(S27:S30) -> 0 | T32: =T24-SUM(T27:T30) -> 0 | V32: =V24-SUM(V27:V30) -> 0 | W32: =W24-SUM(W27:W30) -> 0 | X32: =X24-SUM(X27:X30) -> 0 | Y32: =Y24-SUM(Y27:Y30) -> 0 | Z32: =Z24-SUM(Z27:Z30) -> 0 | AA32: =AA24-SUM(AA27:AA30) -> 0 | AB32: =AB24-SUM(AB27:AB30) -> 0 | AC32: =AC24-SUM(AC27:AC30) -> 0 | AE32: =AE24-SUM(AE27:AE30) -> 0 | AF32: =AF24-SUM(AF27:AF30) -> 0 | AG32: =AG24-SUM(AG27:AG30) -> 0 | AH32: =AH24-SUM(AH27:AH30) -> 0 | AI32: =AI24-SUM(AI27:AI30) -> 0 | AJ32: =AJ24-SUM(AJ27:AJ30) -> 0 | AK32: =AK24-SUM(AK27:AK30) -> 0 | AL32: =AL24-SUM(AL27:AL30) -> 0 | AN32: =AN24-SUM(AN27:AN30) -> 0 | AO32: =AO24-SUM(AO27:AO30) -> 0 | AP32: =AP24-SUM(AP27:AP30) -> 0 | AQ32: =AQ24-SUM(AQ27:AQ30) -> 0 | AR32: =AR24-SUM(AR27:AR30) -> 0 | AS32: =AS24-SUM(AS27:AS30) -> 0 | AT32: =AT24-SUM(AT27:AT30) -> 0 | AU32: =AU24-SUM(AU27:AU30) -> 0 | AW32: =AW24-SUM(AW27:AW30) -> 0 | AX32: =AX24-SUM(AX27:AX30) -> 0 | AY32: =AY24-SUM(AY27:AY30) -> 0 | AZ32: =AZ24-SUM(AZ27:AZ30) -> 0 | BA32: =BA24-SUM(BA27:BA30) -> 0 | BB32: =BB24-SUM(BB27:BB30) -> 0 | BC32: =BC24-SUM(BC27:BC30) -> 0 | BD32: =BD24-SUM(BD27:BD30) -> 0
