Workbook
Name entity: #REF!
Name entity1: #REF!
Name scenario: #REF!
Name year: #REF!

Sheet P&L
B2: Project X P&L
B3: (000s)
C5: 2023 | D5: 2024 | E5: 2025 | F5: Q1 | G5: Q2 | H5: Q3 | I5: Q4 | J5: 2026 | K5: Q1 | L5: Q2 | M5: Q3 | N5: Q4 | O5: 2027 | P5: 2028 | Q5: 2029 | R5: 2030 | S5: 2031 | T5: 2032
B6: Net Sales | C6: =SUM(C7:C13) -> 600 | D6: =SUM(D7:D13) -> 700 | E6: =SUM(E7:E13) -> 700 | F6: =SUM(F7:F13) -> 700 | G6: =SUM(G7:G13) -> 700 | H6: =SUM(H7:H13) -> 425.10334 | I6: =SUM(I7:I13) -> 425.10334 | J6: =SUM(J7:J13) -> 2250.2067 | ... T6: =SUM(T7:T13) -> 2075.519
B7: Prod Line 1 | C7: ='Volume Impact'!C35 -> 0 | D7: ='Volume Impact'!D35 -> 100 | E7: ='Volume Impact'!E35 -> 100 | F7: ='Volume Impact'!F35 -> 100 | G7: ='Volume Impact'!G35 -> 100 | H7: ='Volume Impact'!H35 -> 91.654465 | I7: ='Volume Impact'!I35 -> 91.654465 | J7: ='Volume Impact'!J35 -> 383.30893 | ... T7: ='Volume Impact'!T35 -> 353.55195
B8: Prod Line 2 | C8: ='Volume Impact'!C36 -> 100 | D8: ='Volume Impact'!D36 -> 100 | E8: ='Volume Impact'!E36 -> 100 | F8: ='Volume Impact'!F36 -> 100 | G8: ='Volume Impact'!G36 -> 100 | H8: ='Volume Impact'!H36 -> 94.712802 | I8: ='Volume Impact'!I36 -> 94.712802 | J8: ='Volume Impact'!J36 -> 389.4256 | ... T8: ='Volume Impact'!T36 -> 359.19378
B9: Prod Line 3 | C9: ='Volume Impact'!C37 -> 100 | D9: ='Volume Impact'!D37 -> 100 | E9: ='Volume Impact'!E37 -> 100 | F9: ='Volume Impact'!F37 -> 100 | G9: ='Volume Impact'!G37 -> 100 | H9: ='Volume Impact'!H37 -> 11 | I9: ='Volume Impact'!I37 -> 11 | J9: ='Volume Impact'!J37 -> 222 | ... T9: ='Volume Impact'!T37 -> 204.76573
B10: Prod Line 4 | C10: ='Volume Impact'!C38 -> 100 | D10: ='Volume Impact'!D38 -> 100 | E10: ='Volume Impact'!E38 -> 100 | F10: ='Volume Impact'!F38 -> 100 | G10: ='Volume Impact'!G38 -> 100 | H10: ='Volume Impact'!H38 -> 27 | I10: ='Volume Impact'!I38 -> 27 | J10: ='Volume Impact'!J38 -> 254 | ... T10: ='Volume Impact'!T38 -> 234.28151
B11: Prod Line 5 | C11: ='Volume Impact'!C39 -> 100 | D11: ='Volume Impact'!D39 -> 100 | E11: ='Volume Impact'!E39 -> 100 | F11: ='Volume Impact'!F39 -> 100 | G11: ='Volume Impact'!G39 -> 100 | H11: ='Volume Impact'!H39 -> 6.0232685 | I11: ='Volume Impact'!I39 -> 6.0232685 | J11: ='Volume Impact'!J39 -> 212.04654 | ... T11: ='Volume Impact'!T39 -> 195.58497
B12: Prod Line 6 | C12: ='Volume Impact'!C40 -> 100 | D12: ='Volume Impact'!D40 -> 100 | E12: ='Volume Impact'!E40 -> 100 | F12: ='Volume Impact'!F40 -> 100 | G12: ='Volume Impact'!G40 -> 100 | H12: ='Volume Impact'!H40 -> 100 | I12: ='Volume Impact'!I40 -> 100 | J12: ='Volume Impact'!J40 -> 400 | ... T12: ='Volume Impact'!T40 -> 368.94726
B13: Prod Line 7 | C13: ='Volume Impact'!C41 -> 100 | D13: ='Volume Impact'!D41 -> 100 | E13: ='Volume Impact'!E41 -> 100 | F13: ='Volume Impact'!F41 -> 100 | G13: ='Volume Impact'!G41 -> 100 | H13: ='Volume Impact'!H41 -> 94.712802 | I13: ='Volume Impact'!I41 -> 94.712802 | J13: ='Volume Impact'!J41 -> 389.4256 | ... T13: ='Volume Impact'!T41 -> 359.19378
B15: Direct Margin | C15: ='Volume Impact'!C57 -> 700 | D15: ='Volume Impact'!D57 -> 700 | E15: ='Volume Impact'!E57 -> 700 | F15: ='Volume Impact'!F57 -> 700 | G15: ='Volume Impact'!G57 -> 700 | H15: ='Volume Impact'!H57 -> 700 | I15: ='Volume Impact'!I57 -> 700 | J15: ='Volume Impact'!J57 -> 2800 | ... T15: ='Volume Impact'!T57 -> 2800
B16: Direct Margin % | C16: =IFERROR(C15/C$6,0) -> 1.1666667 | D16: =IFERROR(D15/D$6,0) -> 1 | E16: =IFERROR(E15/E$6,0) -> 1 | F16: =IFERROR(F15/F$6,0) -> 1 | G16: =IFERROR(G15/G$6,0) -> 1 | H16: =IFERROR(H15/H$6,0) -> 1.6466584 | I16: =IFERROR(I15/I$6,0) -> 1.6466584 | J16: =IFERROR(J15/J$6,0) -> 1.2443301 | ... T16: =IFERROR(T15/T$6,0) -> 1.3490602
B18: Variances | C18: =OHCOGS!C29 -> 100 | D18: =OHCOGS!D29 -> 100 | E18: =OHCOGS!E29 -> 100 | F18: =OHCOGS!F29 -> 100 | G18: =OHCOGS!G29 -> 100 | H18: =OHCOGS!H29 -> 100 | I18: =OHCOGS!I29 -> 100 | J18: =OHCOGS!J29 -> 400 | ... T18: =OHCOGS!T29 -> 400
B19: OHCOGS | C19: =OHCOGS!C30 -> 100 | D19: =OHCOGS!D30 -> 100 | E19: =OHCOGS!E30 -> 100 | F19: =OHCOGS!F30 -> 100 | G19: =OHCOGS!G30 -> 100 | H19: =OHCOGS!H30 -> 100 | I19: =OHCOGS!I30 -> 100 | J19: =OHCOGS!J30 -> 400 | ... T19: =OHCOGS!T30 -> 400
B21: Gross Profit | C21: =C15-SUM(C18:C19) -> 500 | D21: =D15-SUM(D18:D19) -> 500 | E21: =E15-SUM(E18:E19) -> 500 | F21: =F15-SUM(F18:F19) -> 500 | G21: =G15-SUM(G18:G19) -> 500 | H21: =H15-SUM(H18:H19) -> 500 | I21: =I15-SUM(I18:I19) -> 500 | J21: =J15-SUM(J18:J19) -> 2000 | ... T21: =T15-SUM(T18:T19) -> 2000
B22: Gross Profit % | C22: =IFERROR(C21/C$6,0) -> 0.83333333 | D22: =IFERROR(D21/D$6,0) -> 0.71428571 | E22: =IFERROR(E21/E$6,0) -> 0.71428571 | F22: =IFERROR(F21/F$6,0) -> 0.71428571 | G22: =IFERROR(G21/G$6,0) -> 0.71428571 | H22: =IFERROR(H21/H$6,0) -> 1.1761846 | I22: =IFERROR(I21/I$6,0) -> 1.1761846 | J22: =IFERROR(J21/J$6,0) -> 0.88880725 | ... T22: =IFERROR(T21/T$6,0) -> 0.96361441
B24: R&D | C24: ='Opex HC'!C38 -> 100 | D24: ='Opex HC'!D38 -> 100 | E24: ='Opex HC'!E38 -> 100 | F24: ='Opex HC'!F38 -> 100 | G24: ='Opex HC'!G38 -> 100 | H24: ='Opex HC'!H38 -> 100 | I24: ='Opex HC'!I38 -> 100 | J24: ='Opex HC'!J38 -> 400 | ... T24: ='Opex HC'!T38 -> 400
B25: S&M | C25: ='Opex HC'!C39 -> 100 | D25: ='Opex HC'!D39 -> 100 | E25: ='Opex HC'!E39 -> 100 | F25: ='Opex HC'!F39 -> 100 | G25: ='Opex HC'!G39 -> 100 | H25: ='Opex HC'!H39 -> 100 | I25: ='Opex HC'!I39 -> 100 | J25: ='Opex HC'!J39 -> 400 | ... T25: ='Opex HC'!T39 -> 400
B26: G&A | C26: ='Opex HC'!C40 -> 100 | D26: ='Opex HC'!D40 -> 100 | E26: ='Opex HC'!E40 -> 100 | F26: ='Opex HC'!F40 -> 100 | G26: ='Opex HC'!G40 -> 100 | H26: ='Opex HC'!H40 -> 100 | I26: ='Opex HC'!I40 -> 100 | J26: ='Opex HC'!J40 -> 400 | ... T26: ='Opex HC'!T40 -> 400
B27: All Other Period Expenses | C27: ='Impact to Cash'!C53 -> 100 | D27: ='Impact to Cash'!D53 -> -100 | E27: ='Impact to Cash'!E53 -> 300 | F27: ='Impact to Cash'!F53 -> -10 | G27: ='Impact to Cash'!G53 -> -10 | H27: ='Impact to Cash'!H53 -> -10 | I27: ='Impact to Cash'!I53 -> -10 | J27: ='Impact to Cash'!J53 -> -40 | ... T27: ='Impact to Cash'!T53 -> 0
B28: Restructuring | C28: ='Impact to Cash'!C54 -> 0 | D28: ='Impact to Cash'!D54 -> 0 | E28: ='Impact to Cash'!E54 -> 0 | F28: ='Impact to Cash'!F54 -> 0 | G28: ='Impact to Cash'!G54 -> 200 | H28: ='Impact to Cash'!H54 -> 0 | I28: ='Impact to Cash'!I54 -> 0 | J28: ='Impact to Cash'!J54 -> 200 | ... T28: ='Impact to Cash'!T54 -> 0
B29: Total Period Expenses | C29: =SUM(C24:C28) -> 400 | D29: =SUM(D24:D28) -> 200 | E29: =SUM(E24:E28) -> 600 | F29: =SUM(F24:F28) -> 290 | G29: =SUM(G24:G28) -> 490 | H29: =SUM(H24:H28) -> 290 | I29: =SUM(I24:I28) -> 290 | J29: =SUM(J24:J28) -> 1360 | ... T29: =SUM(T24:T28) -> 1200
B31: Operating Profit | C31: =C21-C29 -> 100 | D31: =D21-D29 -> 300 | E31: =E21-E29 -> -100 | F31: =F21-F29 -> 210 | G31: =G21-G29 -> 10 | H31: =H21-H29 -> 210 | I31: =I21-I29 -> 210 | J31: =J21-J29 -> 640 | ... T31: =T21-T29 -> 800
B32: OP% | C32: =IFERROR(C31/C$6,0) -> 0.16666667 | D32: =IFERROR(D31/D$6,0) -> 0.42857143 | E32: =IFERROR(E31/E$6,0) -> -0.14285714 | F32: =IFERROR(F31/F$6,0) -> 0.3 | G32: =IFERROR(G31/G$6,0) -> 0.014285714 | H32: =IFERROR(H31/H$6,0) -> 0.49399753 | I32: =IFERROR(I31/I$6,0) -> 0.49399753 | J32: =IFERROR(J31/J$6,0) -> 0.28441832 | ... T32: =IFERROR(T31/T$6,0) -> 0.38544576
B34: Non-Operating Expenses (Income)
B35: Taxes
B37: Net Income | C37: =C31-SUM(C34:C35) -> 100 | D37: =D31-SUM(D34:D35) -> 300 | E37: =E31-SUM(E34:E35) -> -100 | F37: =F31-SUM(F34:F35) -> 210 | G37: =G31-SUM(G34:G35) -> 10 | H37: =H31-SUM(H34:H35) -> 210 | I37: =I31-SUM(I34:I35) -> 210 | J37: =J31-SUM(J34:J35) -> 640 | ... T37: =T31-SUM(T34:T35) -> 800

Sheet Volume Impact
C1: Total Net Sales | L1: Direct Margin at Standard
C2: 2023 | D2: 2024 | E2: 2025 | F2: Q1 | G2: Q2 | H2: Q3 | I2: Q4 | L2: 2023 | M2: 2024 | N2: 2025 | O2: Q1 | P2: Q2 | Q2: Q3 | R2: Q4
B3: Prod Line 1 | C3: 0 | D3: 100 | E3: 100 | F3: 100 | G3: 100 | H3: 100 | I3: 100 | K3: Prod Line 1 | L3: 100 | M3: 100 | N3: 100 | O3: 100 | P3: 100 | Q3: 100 | R3: 100
B4: Prod Line 2 | C4: 100 | D4: 100 | E4: 100 | F4: 100 | G4: 100 | H4: 100 | I4: 100 | K4: Prod Line 2 | L4: 100 | M4: 100 | N4: 100 | O4: 100 | P4: 100 | Q4: 100 | R4: 100
B5: Prod Line 3 | C5: 100 | D5: 100 | E5: 100 | F5: 100 | G5: 100 | H5: 100 | I5: 100 | K5: Prod Line 3 | L5: 100 | M5: 100 | N5: 100 | O5: 100 | P5: 100 | Q5: 100 | R5: 100
B6: Prod Line 4 | C6: 100 | D6: 100 | E6: 100 | F6: 100 | G6: 100 | H6: 100 | I6: 100 | K6: Prod Line 4 | L6: 100 | M6: 100 | N6: 100 | O6: 100 | P6: 100 | Q6: 100 | R6: 100
B7: Prod Line 5 | C7: 100 | D7: 100 | E7: 100 | F7: 100 | G7: 100 | H7: 100 | I7: 100 | K7: Prod Line 5 | L7: 100 | M7: 100 | N7: 100 | O7: 100 | P7: 100 | Q7: 100 | R7: 100
B8: Prod Line 6 | C8: 100 | D8: 100 | E8: 100 | F8: 100 | G8: 100 | H8: 100 | I8: 100 | K8: Prod Line 6 | L8: 100 | M8: 100 | N8: 100 | O8: 100 | P8: 100 | Q8: 100 | R8: 100
B9: Prod Line 7 | C9: 100 | D9: 100 | E9: 100 | F9: 100 | G9: 100 | H9: 100 | I9: 100 | K9: Prod Line 7 | L9: 100 | M9: 100 | N9: 100 | O9: 100 | P9: 100 | Q9: 100 | R9: 100
F11: Q1 | G11: Q2 | H11: Q3 | I11: Q4 | O11: 2027 | P11: 2028 | Q11: 2029 | R11: 2030 | S11: 2031 | T11: 2032
B12: Net Sales Impact | F12: Loss (%) | G12: Loss (%) | H12: Loss (%) | I12: Loss (%) | O12: Annual Loss Rate (%) | P12: Annual Loss Rate (%) | Q12: Annual Loss Rate (%) | R12: Annual Loss Rate (%) | S12: Annual Loss Rate (%) | T12: Annual Loss Rate (%)
B13: Prod Line 1 | H13: 0.083455351 | I13: 0.083455351 | Q13: 0.02 | R13: 0.02 | S13: 0.02 | T13: 0.02
B14: Prod Line 2 | H14: 0.052871976 | I14: 0.052871976 | Q14: 0.02 | R14: 0.02 | S14: 0.02 | T14: 0.02
B15: Prod Line 3 | H15: 0.89 | I15: 0.89 | Q15: 0.02 | R15: 0.02 | S15: 0.02 | T15: 0.02
B16: Prod Line 4 | H16: 0.73 | I16: 0.73 | Q16: 0.02 | R16: 0.02 | S16: 0.02 | T16: 0.02
B17: Prod Line 5 | H17: 0.93976731 | I17: 0.93976731 | Q17: 0.02 | R17: 0.02 | S17: 0.02 | T17: 0.02
B18: Prod Line 6 | Q18: 0.02 | R18: 0.02 | S18: 0.02 | T18: 0.02
B19: Prod Line 7 | H19: 0.052871976 | I19: 0.052871976 | Q19: 0.02 | R19: 0.02 | S19: 0.02 | T19: 0.02
B21: DM Impact | F21: Loss (%) | G21: Loss (%) | H21: Loss (%) | I21: Loss (%) | O21: Annual Loss Rate (%) | P21: Annual Loss Rate (%) | Q21: Annual Loss Rate (%) | R21: Annual Loss Rate (%) | S21: Annual Loss Rate (%) | T21: Annual Loss Rate (%)
B22: Prod Line 1
B23: Prod Line 2
B24: Prod Line 3
B25: Prod Line 4
B26: Prod Line 5
B27: Prod Line 6
B28: Prod Line 7
B31: Total Net Sales
B32: Commerical assumptions 000s
C34: 2023 | D34: 2024 | E34: 2025 | F34: Q1 | G34: Q2 | H34: Q3 | I34: Q4 | J34: 2026 | K34: Q1 | L34: Q2 | M34: Q3 | N34: Q4 | O34: 2027 | P34: 2028 | Q34: 2029 | R34: 2030 | S34: 2031 | T34: 2032
B35: Prod Line 1 | C35: =C3 -> 0 | D35: =D3 -> 100 | E35: =E3 -> 100 | F35: =IF(ISBLANK(F13),F3,F3*(1-F13)) -> 100 | G35: =IF(ISBLANK(G13),G3,G3*(1-G13)) -> 100 | H35: =IF(ISBLANK(H13),H3,H3*(1-H13)) -> 91.654465 | I35: =IF(ISBLANK(I13),I3,I3*(1-I13)) -> 91.654465 | J35: =SUM(F35:I35) -> 383.30893 | K35: =$O35/4 -> 95.827232 | L35: =$O35/4 -> 95.827232 | M35: =$O35/4 -> 95.827232 | N35: =$O35/4 -> 95.827232 | O35: =J35*(1-O13) -> 383.30893 | P35: =O35*(1-P13) -> 383.30893 | Q35: =P35*(1-Q13) -> 375.64275 | R35: =Q35*(1-R13) -> 368.1299 | S35: =R35*(1-S13) -> 360.7673 | T35: =S35*(1-T13) -> 353.55195
B36: Prod Line 2 | C36: =C4 -> 100 | D36: =D4 -> 100 | E36: =E4 -> 100 | F36: =IF(ISBLANK(F14),F4,F4*(1-F14)) -> 100 | G36: =IF(ISBLANK(G14),G4,G4*(1-G14)) -> 100 | H36: =IF(ISBLANK(H14),H4,H4*(1-H14)) -> 94.712802 | I36: =IF(ISBLANK(I14),I4,I4*(1-I14)) -> 94.712802 | J36: =SUM(F36:I36) -> 389.4256 | K36: =$O36/4 -> 97.356401 | L36: =$O36/4 -> 97.356401 | M36: =$O36/4 -> 97.356401 | N36: =$O36/4 -> 97.356401 | O36: =J36*(1-O14) -> 389.4256 | P36: =O36*(1-P14) -> 389.4256 | Q36: =P36*(1-Q14) -> 381.63709 | R36: =Q36*(1-R14) -> 374.00435 | S36: =R36*(1-S14) -> 366.52426 | T36: =S36*(1-T14) -> 359.19378
B37: Prod Line 3 | C37: =C5 -> 100 | D37: =D5 -> 100 | E37: =E5 -> 100 | F37: =IF(ISBLANK(F15),F5,F5*(1-F15)) -> 100 | G37: =IF(ISBLANK(G15),G5,G5*(1-G15)) -> 100 | H37: =IF(ISBLANK(H15),H5,H5*(1-H15)) -> 11 | I37: =IF(ISBLANK(I15),I5,I5*(1-I15)) -> 11 | J37: =SUM(F37:I37) -> 222 | K37: =$O37/4 -> 55.5 | L37: =$O37/4 -> 55.5 | M37: =$O37/4 -> 55.5 | N37: =$O37/4 -> 55.5 | O37: =J37*(1-O15) -> 222 | P37: =O37*(1-P15) -> 222 | Q37: =P37*(1-Q15) -> 217.56 | R37: =Q37*(1-R15) -> 213.2088 | S37: =R37*(1-S15) -> 208.94462 | T37: =S37*(1-T15) -> 204.76573
B38: Prod Line 4 | C38: =C6 -> 100 | D38: =D6 -> 100 | E38: =E6 -> 100 | F38: =IF(ISBLANK(F16),F6,F6*(1-F16)) -> 100 | G38: =IF(ISBLANK(G16),G6,G6*(1-G16)) -> 100 | H38: =IF(ISBLANK(H16),H6,H6*(1-H16)) -> 27 | I38: =IF(ISBLANK(I16),I6,I6*(1-I16)) -> 27 | J38: =SUM(F38:I38) -> 254 | K38: =$O38/4 -> 63.5 | L38: =$O38/4 -> 63.5 | M38: =$O38/4 -> 63.5 | N38: =$O38/4 -> 63.5 | O38: =J38*(1-O16) -> 254 | P38: =O38*(1-P16) -> 254 | Q38: =P38*(1-Q16) -> 248.92 | R38: =Q38*(1-R16) -> 243.9416 | S38: =R38*(1-S16) -> 239.06277 | T38: =S38*(1-T16) -> 234.28151
B39: Prod Line 5 | C39: =C7 -> 100 | D39: =D7 -> 100 | E39: =E7 -> 100 | F39: =IF(ISBLANK(F17),F7,F7*(1-F17)) -> 100 | G39: =IF(ISBLANK(G17),G7,G7*(1-G17)) -> 100 | H39: =IF(ISBLANK(H17),H7,H7*(1-H17)) -> 6.0232685 | I39: =IF(ISBLANK(I17),I7,I7*(1-I17)) -> 6.0232685 | J39: =SUM(F39:I39) -> 212.04654 | K39: =$O39/4 -> 53.011634 | L39: =$O39/4 -> 53.011634 | M39: =$O39/4 -> 53.011634 | N39: =$O39/4 -> 53.011634 | O39: =J39*(1-O17) -> 212.04654 | P39: =O39*(1-P17) -> 212.04654 | Q39: =P39*(1-Q17) -> 207.80561 | R39: =Q39*(1-R17) -> 203.64949 | S39: =R39*(1-S17) -> 199.5765 | T39: =S39*(1-T17) -> 195.58497
B40: Prod Line 6 | C40: =C8 -> 100 | D40: =D8 -> 100 | E40: =E8 -> 100 | F40: =IF(ISBLANK(F18),F8,F8*(1-F18)) -> 100 | G40: =IF(ISBLANK(G18),G8,G8*(1-G18)) -> 100 | H40: =IF(ISBLANK(H18),H8,H8*(1-H18)) -> 100 | I40: =IF(ISBLANK(I18),I8,I8*(1-I18)) -> 100 | J40: =SUM(F40:I40) -> 400 | K40: =$O40/4 -> 100 | L40: =$O40/4 -> 100 | M40: =$O40/4 -> 100 | N40: =$O40/4 -> 100 | O40: =J40*(1-O18) -> 400 | P40: =O40*(1-P18) -> 400 | Q40: =P40*(1-Q18) -> 392 | R40: =Q40*(1-R18) -> 384.16 | S40: =R40*(1-S18) -> 376.4768 | T40: =S40*(1-T18) -> 368.94726
B41: Prod Line 7 | C41: =C9 -> 100 | D41: =D9 -> 100 | E41: =E9 -> 100 | F41: =IF(ISBLANK(F19),F9,F9*(1-F19)) -> 100 | G41: =IF(ISBLANK(G19),G9,G9*(1-G19)) -> 100 | H41: =IF(ISBLANK(H19),H9,H9*(1-H19)) -> 94.712802 | I41: =IF(ISBLANK(I19),I9,I9*(1-I19)) -> 94.712802 | J41: =SUM(F41:I41) -> 389.4256 | K41: =$O41/4 -> 97.356401 | L41: =$O41/4 -> 97.356401 | M41: =$O41/4 -> 97.356401 | N41: =$O41/4 -> 97.356401 | O41: =J41*(1-O19) -> 389.4256 | P41: =O41*(1-P19) -> 389.4256 | Q41: =P41*(1-Q19) -> 381.63709 | R41: =Q41*(1-R19) -> 374.00435 | S41: =R41*(1-S19) -> 366.52426 | T41: =S41*(1-T19) -> 359.19378
B42: All Products | C42: =SUM(C35:C41) -> 600 | D42: =SUM(D35:D41) -> 700 | E42: =SUM(E35:E41) -> 700 | F42: =SUM(F35:F41) -> 700 | G42: =SUM(G35:G41) -> 700 | H42: =SUM(H35:H41) -> 425.10334 | I42: =SUM(I35:I41) -> 425.10334 | J42: =SUM(J35:J41) -> 2250.2067 | ... T42: =SUM(T35:T41) -> 2075.519
B46: Direct Margin at Standard
B47: Commerical assumptions 000s
C49: 2023 | D49: 2024 | E49: 2025 | F49: Q1 | G49: Q2 | H49: Q3 | I49: Q4 | J49: 2026 | K49: Q1 | L49: Q2 | M49: Q3 | N49: Q4 | O49: 2027 | P49: 2028 | Q49: 2029 | R49: 2030 | S49: 2031 | T49: 2032
...

Sheet OHCOGS
C1: Expenses by year | M1: Expenses by Product
C2: 2023 | D2: 2024 | E2: 2025 | F2: Q1 | G2: Q2 | H2: Q3 | I2: Q4 | M2: AMO | N2: SVC | O2: ATG | P2: STP | Q2: Vapor | R2: Orpak POS | S2: Other Products | T2: All Products
B3: Variances | C3: 100 | D3: 100 | E3: 100 | F3: 100 | G3: 100 | H3: 100 | I3: 100 | L3: Variances | M3: 100 | N3: 100 | O3: 100 | P3: 100 | Q3: 100 | R3: 100 | S3: 100 | T3: 100
B4: OHCOGS | C4: 100 | D4: 100 | E4: 100 | F4: 100 | G4: 100 | H4: 100 | I4: 100 | L4: OHCOGS | M4: 100 | N4: 100 | O4: 100 | P4: 100 | Q4: 100 | R4: 100 | S4: 100 | T4: 100
C12: 2023 | D12: 2024 | E12: 2025 | F12: Q1 | G12: Q2 | H12: Q3 | I12: Q4
F13: % Change | G13: % Change | H13: % Change | I13: % Change
B14: Variances
B15: OHCOGS
B25: Overhead
B26: Commerical assumptions 000s
C28: 2023 | D28: 2024 | E28: 2025 | F28: Q1 | G28: Q2 | H28: Q3 | I28: Q4 | J28: 2026 | K28: Q1 | L28: Q2 | M28: Q3 | N28: Q4 | O28: 2027 | P28: 2028 | Q28: 2029 | R28: 2030 | S28: 2031 | T28: 2032
B29: Variances | C29: =C3 -> 100 | D29: =D3 -> 100 | E29: =E3 -> 100 | F29: =F3*(1+F14) -> 100 | G29: =G3*(1+G14) -> 100 | H29: =H3*(1+H14) -> 100 | I29: =I3*(1+I14) -> 100 | J29: =SUM(F29:I29) -> 400 | K29: =$O29/4 -> 100 | L29: =$O29/4 -> 100 | M29: =$O29/4 -> 100 | N29: =$O29/4 -> 100 | O29: =J29 -> 400 | P29: =O29 -> 400 | Q29: =P29 -> 400 | R29: =Q29 -> 400 | S29: =R29 -> 400 | T29: =S29 -> 400
B30: OHCOGS | C30: =C4 -> 100 | D30: =D4 -> 100 | E30: =E4 -> 100 | F30: =F4*(1+F15) -> 100 | G30: =G4*(1+G15) -> 100 | H30: =H4*(1+H15) -> 100 | I30: =I4*(1+I15) -> 100 | J30: =SUM(F30:I30) -> 400 | K30: =$I30 -> 100 | L30: =$I30 -> 100 | M30: =$I30 -> 100 | N30: =$I30 -> 100 | O30: =SUM(K30:N30) -> 400 | P30: =O30 -> 400 | Q30: =P30 -> 400 | R30: =Q30 -> 400 | S30: =R30 -> 400 | T30: =S30 -> 400

Sheet Opex HC
C1: Expenses by year | X1: Expenses by Product
C2: 2023 | D2: 2024 | E2: 2025 | F2: Q1 | G2: Q2 | H2: Q3 | I2: Q4 | X2: AMO | Y2: SVC | Z2: ATG | AA2: STP | AB2: Vapor | AC2: Orpak POS | AD2: Other Products | AE2: All Products
B3: Variances | C3: 100 | D3: 100 | E3: 100 | F3: 100 | G3: 100 | H3: 100 | I3: 100 | W3: Variances | X3: 100 | Y3: 100 | Z3: 100 | AA3: 100 | AB3: 100 | AC3: 100 | AD3: 100 | AE3: 100
B4: OHCOGS | C4: 100 | D4: 100 | E4: 100 | F4: 100 | G4: 100 | H4: 100 | I4: 100 | W4: OHCOGS | X4: 100 | Y4: 100 | Z4: 100 | AA4: 100 | AB4: 100 | AC4: 100 | AD4: 100 | AE4: 100
B5: R&D | C5: 100 | D5: 100 | E5: 100 | F5: 100 | G5: 100 | H5: 100 | I5: 100 | W5: R&D | X5: 100 | Y5: 100 | Z5: 100 | AA5: 100 | AB5: 100 | AC5: 100 | AD5: 100 | AE5: 100
B6: S&M | C6: 100 | D6: 100 | E6: 100 | F6: 100 | G6: 100 | H6: 100 | I6: 100 | W6: S&M | X6: 100 | Y6: 100 | Z6: 100 | AA6: 100 | AB6: 100 | AC6: 100 | AD6: 100 | AE6: 100
B7: G&A | C7: 100 | D7: 100 | E7: 100 | F7: 100 | G7: 100 | H7: 100 | I7: 100 | W7: G&A | X7: 100 | Y7: 100 | Z7: 100 | AA7: 100 | AB7: 100 | AC7: 100 | AD7: 100 | AE7: 100
B8: All other Period Exp | C8: 100 | D8: 100 | E8: 100 | F8: 100 | G8: 100 | H8: 100 | I8: 100 | W8: All other Period Exp | X8: 100 | Y8: 100 | Z8: 100 | AA8: 100 | AB8: 100 | AC8: 100 | AD8: 100 | AE8: 100
B9: Restructuring | C9: 100 | D9: 100 | E9: 100 | F9: 100 | G9: 100 | H9: 100 | I9: 100 | W9: Restructuring | X9: 100 | Y9: 100 | Z9: 100 | AA9: 100 | AB9: 100 | AC9: 100 | AD9: 100 | AE9: 100
F17: Q1 | G17: Q2 | H17: Q3 | I17: Q4 | K17: Q1 | L17: Q2 | M17: Q3 | N17: Q4 | P17: 2028 | Q17: 2029 | R17: 2030 | S17: 2031 | T17: 2032
F18: %Reduction of ppl costs | G18: %Reduction of ppl costs | H18: %Reduction of ppl costs | I18: %Reduction of ppl costs | K18: %Reduction of ppl costs | L18: %Reduction of ppl costs | M18: %Reduction of ppl costs | N18: %Reduction of ppl costs | P18: %Reduction of ppl costs | Q18: %Reduction of ppl costs | R18: %Reduction of ppl costs | S18: %Reduction of ppl costs | T18: %Reduction of ppl costs
B19: R&D
B20: S&M
B21: G&A
F23: Addl %Reduction from non-ppl costs | G23: Addl %Reduction from non-ppl costs | H23: Addl %Reduction from non-ppl costs | I23: Addl %Reduction from non-ppl costs | K23: Addl %Reduction from non-ppl costs | L23: Addl %Reduction from non-ppl costs | M23: Addl %Reduction from non-ppl costs | N23: Addl %Reduction from non-ppl costs | P23: Addl %Reduction from non-ppl costs | Q23: Addl %Reduction from non-ppl costs | R23: Addl %Reduction from non-ppl costs | S23: Addl %Reduction from non-ppl costs | T23: Addl %Reduction from non-ppl costs
B24: R&D
B25: S&M
B26: G&A
F28: Total %Reduction | G28: Total %Reduction | H28: Total %Reduction | I28: Total %Reduction | K28: Total %Reduction | L28: Total %Reduction | M28: Total %Reduction | N28: Total %Reduction | P28: Total %Reduction | Q28: Total %Reduction | R28: Total %Reduction | S28: Total %Reduction | T28: Total %Reduction
B29: R&D | F29: =F19+F24 -> 0 | G29: =G19+G24 -> 0 | H29: =H19+H24 -> 0 | I29: =I19+I24 -> 0 | K29: =K19+K24 -> 0 | L29: =L19+L24 -> 0 | M29: =M19+M24 -> 0 | N29: =N19+N24 -> 0 | P29: =P19+P24 -> 0 | Q29: =Q19+Q24 -> 0 | R29: =R19+R24 -> 0 | S29: =S19+S24 -> 0 | T29: =T19+T24 -> 0
B30: S&M | F30: =F20+F25 -> 0 | G30: =G20+G25 -> 0 | H30: =H20+H25 -> 0 | I30: =I20+I25 -> 0 | K30: =K20+K25 -> 0 | L30: =L20+L25 -> 0 | M30: =M20+M25 -> 0 | N30: =N20+N25 -> 0 | P30: =P20+P25 -> 0 | Q30: =Q20+Q25 -> 0 | R30: =R20+R25 -> 0 | S30: =S20+S25 -> 0 | T30: =T20+T25 -> 0
B31: G&A | F31: =F21+F26 -> 0 | G31: =G21+G26 -> 0 | H31: =H21+H26 -> 0 | I31: =I21+I26 -> 0 | K31: =K21+K26 -> 0 | L31: =L21+L26 -> 0 | M31: =M21+M26 -> 0 | N31: =N21+N26 -> 0 | P31: =P21+P26 -> 0 | Q31: =Q21+Q26 -> 0 | R31: =R21+R26 -> 0 | S31: =S21+S26 -> 0 | T31: =T21+T26 -> 0
B34: Opex
B35: Commerical assumptions 000s
C37: 2023 | D37: 2024 | E37: 2025 | F37: Q1 | G37: Q2 | H37: Q3 | I37: Q4 | J37: 2026 | K37: Q1 | L37: Q2 | M37: Q3 | N37: Q4 | O37: 2027 | P37: 2028 | Q37: 2029 | R37: 2030 | S37: 2031 | T37: 2032
B38: R&D | C38: =C6 -> 100 | D38: =D6 -> 100 | E38: =E6 -> 100 | F38: =F5*(1-F29) -> 100 | G38: =G5*(1-G29) -> 100 | H38: =H5*(1-H29) -> 100 | I38: =I5*(1-I29) -> 100 | J38: =SUM(F38:I38) -> 400 | K38: =I38*(1-K29) -> 100 | L38: =K38*(1-L29) -> 100 | M38: =L38*(1-M29) -> 100 | N38: =M38*(1-N29) -> 100 | O38: =SUM(K38:N38) -> 400 | P38: =O38*(1-P29) -> 400 | Q38: =P38*(1-Q29) -> 400 | R38: =Q38*(1-R29) -> 400 | S38: =R38*(1-S29) -> 400 | T38: =S38*(1-T29) -> 400
B39: S&M | C39: =C7 -> 100 | D39: =D7 -> 100 | E39: =E7 -> 100 | F39: =F6*(1-F30) -> 100 | G39: =G6*(1-G30) -> 100 | H39: =H6*(1-H30) -> 100 | I39: =I6*(1-I30) -> 100 | J39: =SUM(F39:I39) -> 400 | K39: =I39*(1-K30) -> 100 | L39: =K39*(1-L30) -> 100 | M39: =L39*(1-M30) -> 100 | N39: =M39*(1-N30) -> 100 | O39: =SUM(K39:N39) -> 400 | P39: =O39*(1-P30) -> 400 | Q39: =P39*(1-Q30) -> 400 | R39: =Q39*(1-R30) -> 400 | S39: =R39*(1-S30) -> 400 | T39: =S39*(1-T30) -> 400
B40: G&A | C40: =C8 -> 100 | D40: =D8 -> 100 | E40: =E8 -> 100 | F40: =F7*(1-F31) -> 100 | G40: =G7*(1-G31) -> 100 | H40: =H7*(1-H31) -> 100 | I40: =I7*(1-I31) -> 100 | J40: =SUM(F40:I40) -> 400 | K40: =I40*(1-K31) -> 100 | L40: =K40*(1-L31) -> 100 | M40: =L40*(1-M31) -> 100 | N40: =M40*(1-N31) -> 100 | O40: =SUM(K40:N40) -> 400 | P40: =O40*(1-P31) -> 400 | Q40: =P40*(1-Q31) -> 400 | R40: =Q40*(1-R31) -> 400 | S40: =R40*(1-S31) -> 400 | T40: =S40*(1-T31) -> 400
B41: Total | C41: =SUM(C38:C40) -> 300 | D41: =SUM(D38:D40) -> 300 | E41: =SUM(E38:E40) -> 300 | F41: =SUM(F38:F40) -> 300 | G41: =SUM(G38:G40) -> 300 | H41: =SUM(H38:H40) -> 300 | I41: =SUM(I38:I40) -> 300 | J41: =SUM(J38:J40) -> 1200 | ... T41: =SUM(T38:T40) -> 1200

Sheet Cash
B3: Project X Cash Flow
B4: (000s)
C6: 2023 | D6: 2024 | E6: 2025 | F6: Q1 | G6: Q2 | H6: Q3 | I6: Q4 | J6: 2026 | K6: Q1 | L6: Q2 | M6: Q3 | N6: Q4 | O6: 2027 | P6: 2028 | Q6: 2029 | R6: 2030 | S6: 2031 | T6: 2032
B7: Operating Income | C7: ='P&L'!C37 -> 100 | D7: ='P&L'!D37 -> 300 | E7: ='P&L'!E37 -> -100 | F7: ='P&L'!F37 -> 210 | G7: ='P&L'!G37 -> 10 | H7: ='P&L'!H37 -> 210 | I7: ='P&L'!I37 -> 210 | J7: ='P&L'!J37 -> 640 | ... T7: ='P&L'!T37 -> 800
B9: Depreciation & Amortization (+) | C9: ='Impact to Cash'!C57 -> 0 | D9: ='Impact to Cash'!D57 -> 0 | E9: ='Impact to Cash'!E57 -> 0 | F9: ='Impact to Cash'!F57 -> 0 | G9: ='Impact to Cash'!G57 -> 0 | H9: ='Impact to Cash'!H57 -> 0 | I9: ='Impact to Cash'!I57 -> 0 | J9: ='Impact to Cash'!J57 -> 0 | ... T9: ='Impact to Cash'!T57 -> 0
B10: Change in Working Capital (+/-) | C10: ='Impact to Cash'!C55 -> 0 | D10: ='Impact to Cash'!D55 -> 0 | E10: 0 | F10: ='Impact to Cash'!F55 -> 0 | G10: ='Impact to Cash'!G55 -> 0 | H10: ='Impact to Cash'!H55 -> 0 | I10: ='Impact to Cash'!I55 -> 0 | J10: ='Impact to Cash'!J55 -> 0 | K10: ='Impact to Cash'!K55 -> 0 | L10: ='Impact to Cash'!L55 -> 0 | M10: ='Impact to Cash'!M55 -> 0 | ... T10: ='Impact to Cash'!T55 -> 0
B12: Cash Flow from Operating Act. | C12: =C7+SUM(C9:C10) -> 100 | D12: =D7+SUM(D9:D10) -> 300 | E12: =E7+SUM(E9:E10) -> -100 | F12: =F7+SUM(F9:F10) -> 210 | G12: =G7+SUM(G9:G10) -> 10 | H12: =H7+SUM(H9:H10) -> 210 | I12: =I7+SUM(I9:I10) -> 210 | J12: =J7+SUM(J9:J10) -> 640 | ... T12: =T7+SUM(T9:T10) -> 800
B14: Capital Expenditures | C14: ='Impact to Cash'!C56 -> 0 | D14: ='Impact to Cash'!D56 -> 0 | E14: ='Impact to Cash'!E56 -> 0 | F14: ='Impact to Cash'!F56 -> 0 | G14: ='Impact to Cash'!G56 -> 0 | H14: ='Impact to Cash'!H56 -> 0 | I14: ='Impact to Cash'!I56 -> 0 | J14: ='Impact to Cash'!J56 -> 0 | ... T14: ='Impact to Cash'!T56 -> 0
B16: Cash Flow from Investment Act. | C16: =SUM(C14) -> 0 | D16: =SUM(D14) -> 0 | E16: =SUM(E14) -> 0 | F16: =SUM(F14) -> 0 | G16: =SUM(G14) -> 0 | H16: =SUM(H14) -> 0 | I16: =SUM(I14) -> 0 | J16: =SUM(J14) -> 0 | ... T16: =SUM(T14) -> 0
B18: Changes in Cash | C18: =C12+C16 -> 100 | D18: =D12+D16 -> 300 | E18: =E12+E16 -> -100 | F18: =F12+F16 -> 210 | G18: =G12+G16 -> 10 | H18: =H12+H16 -> 210 | I18: =I12+I16 -> 210 | J18: =J12+J16 -> 640 | ... T18: =T12+T16 -> 800
B20: Cash at Start of Period | E20: =D21 -> 300 | F20: =E21 -> 230 | G20: =F21 -> 440 | H20: =G21 -> 450 | I20: =H21 -> 660 | J20: =F20 -> 230 | K20: =I21 -> 870 | L20: =K21 -> 1070 | M20: =L21 -> 1270 | N20: =M21 -> 1470 | O20: =K20 -> 870 | P20: =O21 -> 1670 | Q20: =P21 -> 2470 | R20: =Q21 -> 3270 | S20: =R21 -> 4070 | T20: =S21 -> 4870
B21: Cash at End of Period | C21: =C20+C18 -> 100 | D21: =D20+D18 -> 300 | E21: 230 | F21: =F20+F18 -> 440 | G21: =G20+G18 -> 450 | H21: =H20+H18 -> 660 | I21: =I20+I18 -> 870 | J21: =J20+J18 -> 870 | K21: =K20+K18 -> 1070 | L21: =L20+L18 -> 1270 | M21: =M20+M18 -> 1470 | ... T21: =T20+T18 -> 5670
B45: Ref
B46: Operating Income
B47: Depreciation & Amortizations
B48: Changes in Working Capital
B49: Cash Flow From Operating Activities | C49: =SUM(C47:C48) -> 0
B50: Capital Expenditures
B51: Acquisitions
B52: Sales of Investments
B53: Cash Flow from Investment Act | C53: =SUM(C50:C52) -> 0
B54: Changes in Debt Balance
B55: Issue/Repurchase Stock
B56: Dividend Payouts
B57: Cash Flow from Financing Act | C57: =SUM(C54:C56) -> 0
B58: Changes in Cash | C58: =C49+C53+C57 -> 0
B59: Cash at Start of Period
B60: Cash at End of Period | C60: =C59+C58 -> 0

Sheet Impact to Cash
C1: 2023 | D1: 2024 | E1: 2025 | F1: Q1 | G1: Q2 | H1: Q3 | I1: Q4 | K1: Q1 | L1: Q2 | M1: Q3 | N1: Q4 | P1: 2028 | Q1: 2029 | R1: 2030 | S1: 2031 | T1: 2032 | X1: 2023 | Y1: 2024 | Z1: 2025 | AA1: Q1 | AB1: Q2 | AC1: Q3 | AD1: Q4 | AE1: Q1 | AF1: Q2 | AG1: Q3 | AH1: Q4
W2: All other Period Exp | X2: 100 | Y2: -100 | Z2: 300 | AE2: -10 | AF2: -10 | AG2: -10 | AH2: -10
B3: All other Period Expenses | F3: $ | G3: $ | H3: $ | I3: $ | K3: $ | L3: $ | M3: $ | N3: $ | P3: $ | Q3: $ | R3: $ | S3: $ | T3: $ | W3: Restructuring | X3: 0 | Y3: 0 | Z3: 0 | AE3: 0 | AF3: 200 | AG3: 0 | AH3: 0
W4: Working Capital | Z4: 4000 | AA4: 4000 | AB4: 4000 | AC4: 4000 | AD4: 4000 | AE4: 4000 | AF4: 4000 | AG4: 4000 | AH4: 4000
W6: Raw Material Purchases | AE6: 0 | AF6: 0 | AG6: 0 | AH6: 0
B8: Total Impact to Period Expenses | F8: =SUM(F4:F7) -> 0 | G8: =SUM(G4:G7) -> 0 | H8: =SUM(H4:H7) -> 0 | I8: =SUM(I4:I7) -> 0 | K8: =SUM(K4:K7) -> 0 | L8: =SUM(L4:L7) -> 0 | M8: =SUM(M4:M7) -> 0 | N8: =SUM(N4:N7) -> 0 | P8: =SUM(P4:P7) -> 0 | Q8: =SUM(Q4:Q7) -> 0 | R8: =SUM(R4:R7) -> 0 | S8: =SUM(S4:S7) -> 0 | T8: =SUM(T4:T7) -> 0
B12: Restructuring | F12: $ | G12: $ | H12: $ | I12: $ | K12: $ | L12: $ | M12: $ | N12: $ | P12: $ | Q12: $ | R12: $ | S12: $ | T12: $
B13: Transfer of Equipment & Inventory
B14: Legal Expenses
B15: New IT Setup
B16: Total Impact to Restructuring | F16: =SUM(F13:F15) -> 0 | G16: =SUM(G13:G15) -> 0 | H16: =SUM(H13:H15) -> 0 | I16: =SUM(I13:I15) -> 0 | K16: =SUM(K13:K15) -> 0 | L16: =SUM(L13:L15) -> 0 | M16: =SUM(M13:M15) -> 0 | N16: =SUM(N13:N15) -> 0 | P16: =SUM(P13:P15) -> 0 | Q16: =SUM(Q13:Q15) -> 0 | R16: =SUM(R13:R15) -> 0 | S16: =SUM(S13:S15) -> 0 | T16: =SUM(T13:T15) -> 0
B19: Changes to Working Capital | F19: $ | G19: $ | H19: $ | I19: $ | K19: $ | L19: $ | M19: $ | N19: $ | P19: $ | Q19: $ | R19: $ | S19: $ | T19: $
B20: Prod Line 1
B21: Prod Line 2
B22: Prod Line 3
B23: Prod Line 4
B24: Prod Line 5
B25: Prod Line 6
B26: Prod Line 7
B27: Raw Material Purchases | F27: =SUM(F20:F26) -> 0 | G27: =SUM(G20:G26) -> 0 | H27: =SUM(H20:H26) -> 0 | I27: =SUM(I20:I26) -> 0 | K27: =SUM(K20:K26) -> 0 | L27: =SUM(L20:L26) -> 0 | M27: =SUM(M20:M26) -> 0 | N27: =SUM(N20:N26) -> 0 | P27: =SUM(P20:P26) -> 0 | Q27: =SUM(Q20:Q26) -> 0 | R27: =SUM(R20:R26) -> 0 | S27: =SUM(S20:S26) -> 0 | T27: =SUM(T20:T26) -> 0
B28: Severances & Shutdown Costs
B29: Inventory Write Downs
B30: Lease Termination Penalties
B31: Asset Liquidation
B32: Accounts Payable
B33: Total Var to Working Capital | F33: =SUM(F28:F32) -> 0 | G33: =SUM(G28:G32) -> 0 | H33: =SUM(H28:H32) -> 0 | I33: =SUM(I28:I32) -> 0 | K33: =SUM(K28:K32) -> 0 | L33: =SUM(L28:L32) -> 0 | M33: =SUM(M28:M32) -> 0 | N33: =SUM(N28:N32) -> 0 | P33: =SUM(P28:P32) -> 0 | Q33: =SUM(Q28:Q32) -> 0 | R33: =SUM(R28:R32) -> 0 | S33: =SUM(S28:S32) -> 0 | T33: =SUM(T28:T32) -> 0
B36: Capital Expenditures | F36: $ | G36: $ | H36: $ | I36: $ | K36: $ | L36: $ | M36: $ | N36: $ | P36: $ | Q36: $ | R36: $ | S36: $ | T36: $
B37: Equipment (Setup)
B41: Total Capital Expenditures | F41: =SUM(F37:F40) -> 0 | G41: =SUM(G37:G40) -> 0 | H41: =SUM(H37:H40) -> 0 | I41: =SUM(I37:I40) -> 0 | K41: =SUM(K37:K40) -> 0 | L41: =SUM(L37:L40) -> 0 | M41: =SUM(M37:M40) -> 0 | N41: =SUM(N37:N40) -> 0 | P41: =SUM(P37:P40) -> 0 | Q41: =SUM(Q37:Q40) -> 0 | R41: =SUM(R37:R40) -> 0 | S41: =SUM(S37:S40) -> 0 | T41: =SUM(T37:T40) -> 0
B43: Depreciation & Amortization | F43: $ | G43: $ | H43: $ | I43: $ | K43: $ | L43: $ | M43: $ | N43: $ | P43: $ | Q43: $ | R43: $ | S43: $ | T43: $
B44: Depreciation
B45: Amortization
B46: Total Depreciation & Amortization | F46: =SUM(F44:F45) -> 0 | G46: =SUM(G44:G45) -> 0 | H46: =SUM(H44:H45) -> 0 | I46: =SUM(I44:I45) -> 0 | K46: =SUM(K44:K45) -> 0 | L46: =SUM(L44:L45) -> 0 | M46: =SUM(M44:M45) -> 0 | N46: =SUM(N44:N45) -> 0 | P46: =SUM(P44:P45) -> 0 | Q46: =SUM(Q44:Q45) -> 0 | R46: =SUM(R44:R45) -> 0 | S46: =SUM(S44:S45) -> 0 | T46: =SUM(T44:T45) -> 0
B49: Opex
B50: Commerical assumptions 000s
C52: 2023 | D52: 2024 | E52: 2025 | F52: Q1 | G52: Q2 | H52: Q3 | I52: Q4 | J52: 2026 | K52: Q1 | L52: Q2 | M52: Q3 | N52: Q4 | O52: 2027 | P52: 2028 | Q52: 2029 | R52: 2030 | S52: 2031 | T52: 2032
B53: All other Period Exp | C53: =X2 -> 100 | D53: =Y2 -> -100 | E53: =Z2 -> 300 | F53: =AE2+F8 -> -10 | G53: =AF2+G8 -> -10 | H53: =AG2+H8 -> -10 | I53: =AH2+I8 -> -10 | J53: =SUM(F53:I53) -> -40 | K53: =K8 -> 0 | L53: =L8 -> 0 | M53: =M8 -> 0 | N53: =N8 -> 0 | O53: =SUM(K53:N53) -> 0 | P53: =P8 -> 0 | Q53: =Q8 -> 0 | R53: =R8 -> 0 | S53: =S8 -> 0 | T53: =T8 -> 0
B54: Restructuring | C54: =X3 -> 0 | D54: =Y3 -> 0 | E54: =Z3 -> 0 | F54: =AE3+F16 -> 0 | G54: =AF3+G16 -> 200 | H54: =AG3+H16 -> 0 | I54: =AH3+I16 -> 0 | J54: =SUM(F54:I54) -> 200 | K54: =K16 -> 0 | L54: =L16 -> 0 | M54: =M16 -> 0 | N54: =N16 -> 0 | O54: =SUM(K54:N54) -> 0 | P54: =P16 -> 0 | Q54: =Q16 -> 0 | R54: =R16 -> 0 | S54: =S16 -> 0 | T54: =T16 -> 0
B55: Change in Working Capital | C55: =X4 -> 0 | D55: =Y4 -> 0 | E55: 0 | F55: =F33 -> 0 | G55: =G33 -> 0 | H55: =H33 -> 0 | I55: =I33 -> 0 | J55: =SUM(F55:I55) -> 0 | K55: =K33 -> 0 | L55: =L33 -> 0 | M55: =M33 -> 0 | N55: =N33 -> 0 | O55: =SUM(K55:N55) -> 0 | P55: =P33 -> 0 | Q55: =Q33 -> 0 | R55: =R33 -> 0 | S55: =S33 -> 0 | T55: =T33 -> 0
B56: Capital Expenditures | F56: =F41 -> 0 | G56: =G41 -> 0 | H56: =H41 -> 0 | I56: =I41 -> 0 | J56: =SUM(F56:I56) -> 0 | K56: =K41 -> 0 | L56: =L41 -> 0 | M56: =M41 -> 0 | N56: =N41 -> 0 | O56: =SUM(K56:N56) -> 0 | P56: =P41 -> 0 | Q56: =Q41 -> 0 | R56: =R41 -> 0 | S56: =S41 -> 0 | T56: =T41 -> 0
...
